Workbook

Sheet Summary
A1: Tech DCF Valuation — Summary
A2: Every column here is a live link into that company's own sheet — edit assumptions on a company tab and this table updates.
A3: "Price (input)" / "Shares O/S" default to a market close snapshot from 2026-07-30 -- edit those two highlighted cells any time to re-run the comparison with a current quote.
A4: Ticker | B4: Company | C4: WACC | D4: Terminal growth | E4: FY revenue ($M) | F4: Enterprise value ($M) | G4: Equity value ($M) | H4: Diluted shares (M) | I4: Implied value/share | J4: Low est. (12% WACC, 2% g) | K4: High est. (8% WACC, 4% g) | L4: Price (input) | M4: Shares O/S, M (input) | N4: Market cap ($M) | O4: DCF vs. market
A5: CRM | B5: Salesforce, Inc. | C5: ='CRM'!B5 | D5: ='CRM'!B6 | E5: ='CRM'!F12 | F5: ='CRM'!B35 | G5: ='CRM'!B38 | H5: ='CRM'!B39 | I5: ='CRM'!B40 | J5: ='CRM'!C48 | K5: ='CRM'!G44 | L5: 180.71 | M5: 819 | N5: =L5*M5 | O5: =(G5-N5)/N5
A6: ADBE | B6: Adobe Inc. | C6: ='ADBE'!B5 | D6: ='ADBE'!B6 | E6: ='ADBE'!F12 | F6: ='ADBE'!B35 | G6: ='ADBE'!B38 | H6: ='ADBE'!B39 | I6: ='ADBE'!B40 | J6: ='ADBE'!C48 | K6: ='ADBE'!G44 | L6: 247.9 | M6: 397.5 | N6: =L6*M6 | O6: =(G6-N6)/N6
A7: NOW | B7: ServiceNow, Inc. | C7: ='NOW'!B5 | D7: ='NOW'!B6 | E7: ='NOW'!F12 | F7: ='NOW'!B35 | G7: ='NOW'!B38 | H7: ='NOW'!B39 | I7: ='NOW'!B40 | J7: ='NOW'!C48 | K7: ='NOW'!G44 | L7: 110.07 | M7: 1030 | N7: =L7*M7 | O7: =(G7-N7)/N7
A8: WDAY | B8: Workday, Inc. | C8: ='WDAY'!B5 | D8: ='WDAY'!B6 | E8: ='WDAY'!F12 | F8: ='WDAY'!B35 | G8: ='WDAY'!B38 | H8: ='WDAY'!B39 | I8: ='WDAY'!B40 | J8: ='WDAY'!C48 | K8: ='WDAY'!G44 | L8: 158.11 | M8: 246.97 | N8: =L8*M8 | O8: =(G8-N8)/N8
A9: HUBS | B9: HubSpot Inc | C9: ='HUBS'!B5 | D9: ='HUBS'!B6 | E9: ='HUBS'!F12 | F9: ='HUBS'!B35 | G9: ='HUBS'!B38 | H9: ='HUBS'!B39 | I9: ='HUBS'!B40 | J9: ='HUBS'!C48 | K9: ='HUBS'!G44 | L9: 233.1 | M9: 51.22 | N9: =L9*M9 | O9: =(G9-N9)/N9
A10: TEAM | B10: Atlassian Corp | C10: ='TEAM'!B5 | D10: ='TEAM'!B6 | E10: ='TEAM'!F12 | F10: ='TEAM'!B35 | G10: ='TEAM'!B38 | H10: ='TEAM'!B39 | I10: ='TEAM'!B40 | J10: ='TEAM'!C48 | K10: ='TEAM'!G44 | L10: 98.12 | M10: 253.77 | N10: =L10*M10 | O10: =(G10-N10)/N10
A11: DDOG | B11: Datadog, Inc. | C11: ='DDOG'!B5 | D11: ='DDOG'!B6 | E11: ='DDOG'!F12 | F11: ='DDOG'!B35 | G11: ='DDOG'!B38 | H11: ='DDOG'!B39 | I11: ='DDOG'!B40 | J11: ='DDOG'!C48 | K11: ='DDOG'!G44 | L11: 268.56 | M11: 355.96 | N11: =L11*M11 | O11: =(G11-N11)/N11
A12: SNOW | B12: Snowflake Inc. | C12: ='SNOW'!B5 | D12: ='SNOW'!B6 | E12: ='SNOW'!F12 | F12: ='SNOW'!B35 | G12: ='SNOW'!B38 | H12: ='SNOW'!B39 | I12: ='SNOW'!B40 | J12: ='SNOW'!C48 | K12: ='SNOW'!G44 | L12: 298.1 | M12: 346.6 | N12: =L12*M12 | O12: =(G12-N12)/N12
A13: ZS | B13: Zscaler, Inc. | C13: ='ZS'!B5 | D13: ='ZS'!B6 | E13: ='ZS'!F12 | F13: ='ZS'!B35 | G13: ='ZS'!B38 | H13: ='ZS'!B39 | I13: ='ZS'!B40 | J13: ='ZS'!C48 | K13: ='ZS'!G44 | L13: 148.39 | M13: 161.71 | N13: =L13*M13 | O13: =(G13-N13)/N13
A14: CRWD | B14: CrowdStrike Holdings, Inc. | C14: ='CRWD'!B5 | D14: ='CRWD'!B6 | E14: ='CRWD'!F12 | F14: ='CRWD'!B35 | G14: ='CRWD'!B38 | H14: ='CRWD'!B39 | I14: ='CRWD'!B40 | J14: ='CRWD'!C48 | K14: ='CRWD'!G44 | L14: 185.22 | M14: 1020 | N14: =L14*M14 | O14: =(G14-N14)/N14

Sheet CRM
A1: CRM — Salesforce, Inc.
A2: Unlevered DCF | $ in millions except per-share and share count
A4: Assumptions (edit the highlighted cells)
A5: WACC (discount rate) | B5: 0.1
A6: Terminal growth rate | B6: 0.03
A7: Starting revenue growth rate | B7: 0.095791001 | C7: default: most recent YoY revenue growth
A8: Unlevered FCF margin (% of revenue) | B8: 0.33747219 | C8: default: avg of last 2 fiscal years' FCF / revenue
A10: Historical Trend ($ in millions)
A11: Fiscal year | B11: 2022 | C11: 2023 | D11: 2024 | E11: 2025 | F11: 2026
A12: Revenue | B12: 26492 | C12: 31352 | D12: 34857 | E12: 37895 | F12: 41525
A13: Revenue growth % | C13: =C12/B12-1 | D13: =D12/C12-1 | E13: =E12/D12-1 | F13: =F12/E12-1
A14: Free cash flow | B14: 5283 | C14: 6313 | D14: 9498 | E14: 12434 | F14: 14402
A15: FCF margin % | B15: =B14/B12 | C15: =C14/C12 | D15: =D14/D12 | E15: =E14/E12 | F15: =F14/F12
A17: Balance Sheet Actuals — FY2026 ($ in millions)
A18: Cash & equivalents | B18: 7327
A19: Total debt | B19: 14439
A20: Diluted shares outstanding (millions) | B20: 956
A22: 5-Year Projection ($ in millions)
A23: Fiscal year | B23: FY2027E | C23: FY2028E | D23: FY2029E | E23: FY2030E | F23: FY2031E
A24: Revenue growth rate | B24: =$B$7+($B$6-$B$7)*1/5 | C24: =$B$7+($B$6-$B$7)*2/5 | D24: =$B$7+($B$6-$B$7)*3/5 | E24: =$B$7+($B$6-$B$7)*4/5 | F24: =$B$7+($B$6-$B$7)*5/5
A25: Projected revenue | B25: =F12*(1+B24) | C25: =B25*(1+C24) | D25: =C25*(1+D24) | E25: =D25*(1+E24) | F25: =E25*(1+F24)
A26: FCF margin (assumption, held flat) | B26: =$B$8 | C26: =$B$8 | D26: =$B$8 | E26: =$B$8 | F26: =$B$8
A27: Projected unlevered FCF | B27: =B25*B26 | C27: =C25*C26 | D27: =D25*D26 | E27: =E25*E26 | F27: =F25*F26
A28: Discount factor | B28: =1/(1+$B$5)^1 | C28: =1/(1+$B$5)^2 | D28: =1/(1+$B$5)^3 | E28: =1/(1+$B$5)^4 | F28: =1/(1+$B$5)^5
A29: PV of FCF | B29: =B27*B28 | C29: =C27*C28 | D29: =D27*D28 | E29: =E27*E28 | F29: =F27*F28
A31: Terminal Value & Valuation
A32: Terminal value (end of FY2031) | B32: =F27*(1+$B$6)/($B$5-$B$6)
A33: PV of terminal value | B33: =B32*F28
A34: Sum of PV of projected FCFs | B34: =SUM(B29:F29)
A35: Enterprise value | B35: =B33+B34
A36: Less: total debt | B36: =-B19
A37: Plus: cash & equivalents | B37: =B18
A38: Equity value | B38: =B35+B36+B37
A39: Diluted shares outstanding (millions) | B39: =B20
A40: Implied value per share | B40: =B38/B39
A42: Sensitivity: Implied Value/Share (WACC x Terminal Growth)
B43: WACC \ Term. g | C43: 0.02 | D43: 0.025 | E43: 0.03 | F43: 0.035 | G43: 0.04
B44: 0.08 | C44: =((((($F$12*(1+($B$7+(C$43-$B$7)*1/5)))*$B$8)/(1+$B$44)^1)+((($F$12*(1+($B$7+(C$43-$B$7)*1/5))*(1+($B$7+(C$43-$B$7)*2/5)))*$B$8)/(1+$B$44)^2)+((($F$12*(1+($B$7+(C$43-$B$7)*1/5))*(1+($B$7+(C$43-$B$7)*2/5))*(1+($B$7+(C$43-$B$7)*3/5)))*$B$8)/(1+$B$44)^3)+((($F$12*(1+($B$7+(C$43-$B$7)*1/5))*(1+($B$7+(C$43-$B$7)*2/5))*(1+($B$7+(C$43-$B$7)*3/5))*(1+($B$7+(C$43-$B$7)*4/5)))*$B$8)/(1+$B$44)^4)+((($F$12*(1+($B$7+(C$43-$B$7)*1/5))*(1+($B$7+(C$43-$B$7)*2/5))*(1+($B$7+(C$43-$B$7)*3/5))*(1+($B$7+(C$43-$B$7)*4/5))*(1+($B$7+(C$43-$B$7)*5/5)))*$B$8)/(1+$B$44)^5)+((((($F$12*(1+($B$7+(C$43-$B$7)*1/5))*(1+($B$7+(C$43-$B$7)*2/5))*(1+($B$7+(C$43-$B$7)*3/5))*(1+($B$7+(C$43-$B$7)*4/5))*(1+($B$7+(C$43-$B$7)*5/5)))*$B$8)*(1+C$43))/($B$44-C$43))/(1+$B$44)^5))-$B$19+$B$18)/$B$20 | D44: =((((($F$12*(1+($B$7+(D$43-$B$7)*1/5)))*$B$8)/(1+$B$44)^1)+((($F$12*(1+($B$7+(D$43-$B$7)*1/5))*(1+($B$7+(D$43-$B$7)*2/5)))*$B$8)/(1+$B$44)^2)+((($F$12*(1+($B$7+(D$43-$B$7)*1/5))*(1+($B$7+(D$43-$B$7)*2/5))*(1+($B$7+(D$43-$B$7)*3/5)))*$B$8)/(1+$B$44)^3)+((($F$12*(1+($B$7+(D$43-$B$7)*1/5))*(1+($B$7+(D$43-$B$7)*2/5))*(1+($B$7+(D$43-$B$7)*3/5))*(1+($B$7+(D$43-$B$7)*4/5)))*$B$8)/(1+$B$44)^4)+((($F$12*(1+($B$7+(D$43-$B$7)*1/5))*(1+($B$7+(D$43-$B$7)*2/5))*(1+($B$7+(D$43-$B$7)*3/5))*(1+($B$7+(D$43-$B$7)*4/5))*(1+($B$7+(D$43-$B$7)*5/5)))*$B$8)/(1+$B$44)^5)+((((($F$12*(1+($B$7+(D$43-$B$7)*1/5))*(1+($B$7+(D$43-$B$7)*2/5))*(1+($B$7+(D$43-$B$7)*3/5))*(1+($B$7+(D$43-$B$7)*4/5))*(1+($B$7+(D$43-$B$7)*5/5)))*$B$8)*(1+D$43))/($B$44-D$43))/(1+$B$44)^5))-$B$19+$B$18)/$B$20 | E44: =((((($F$12*(1+($B$7+(E$43-$B$7)*1/5)))*$B$8)/(1+$B$44)^1)+((($F$12*(1+($B$7+(E$43-$B$7)*1/5))*(1+($B$7+(E$43-$B$7)*2/5)))*$B$8)/(1+$B$44)^2)+((($F$12*(1+($B$7+(E$43-$B$7)*1/5))*(1+($B$7+(E$43-$B$7)*2/5))*(1+($B$7+(E$43-$B$7)*3/5)))*$B$8)/(1+$B$44)^3)+((($F$12*(1+($B$7+(E$43-$B$7)*1/5))*(1+($B$7+(E$43-$B$7)*2/5))*(1+($B$7+(E$43-$B$7)*3/5))*(1+($B$7+(E$43-$B$7)*4/5)))*$B$8)/(1+$B$44)^4)+((($F$12*(1+($B$7+(E$43-$B$7)*1/5))*(1+($B$7+(E$43-$B$7)*2/5))*(1+($B$7+(E$43-$B$7)*3/5))*(1+($B$7+(E$43-$B$7)*4/5))*(1+($B$7+(E$43-$B$7)*5/5)))*$B$8)/(1+$B$44)^5)+((((($F$12*(1+($B$7+(E$43-$B$7)*1/5))*(1+($B$7+(E$43-$B$7)*2/5))*(1+($B$7+(E$43-$B$7)*3/5))*(1+($B$7+(E$43-$B$7)*4/5))*(1+($B$7+(E$43-$B$7)*5/5)))*$B$8)*(1+E$43))/($B$44-E$43))/(1+$B$44)^5))-$B$19+$B$18)/$B$20 | F44: =((((($F$12*(1+($B$7+(F$43-$B$7)*1/5)))*$B$8)/(1+$B$44)^1)+((($F$12*(1+($B$7+(F$43-$B$7)*1/5))*(1+($B$7+(F$43-$B$7)*2/5)))*$B$8)/(1+$B$44)^2)+((($F$12*(1+($B$7+(F$43-$B$7)*1/5))*(1+($B$7+(F$43-$B$7)*2/5))*(1+($B$7+(F$43-$B$7)*3/5)))*$B$8)/(1+$B$44)^3)+((($F$12*(1+($B$7+(F$43-$B$7)*1/5))*(1+($B$7+(F$43-$B$7)*2/5))*(1+($B$7+(F$43-$B$7)*3/5))*(1+($B$7+(F$43-$B$7)*4/5)))*$B$8)/(1+$B$44)^4)+((($F$12*(1+($B$7+(F$43-$B$7)*1/5))*(1+($B$7+(F$43-$B$7)*2/5))*(1+($B$7+(F$43-$B$7)*3/5))*(1+($B$7+(F$43-$B$7)*4/5))*(1+($B$7+(F$43-$B$7)*5/5)))*$B$8)/(1+$B$44)^5)+((((($F$12*(1+($B$7+(F$43-$B$7)*1/5))*(1+($B$7+(F$43-$B$7)*2/5))*(1+($B$7+(F$43-$B$7)*3/5))*(1+($B$7+(F$43-$B$7)*4/5))*(1+($B$7+(F$43-$B$7)*5/5)))*$B$8)*(1+F$43))/($B$44-F$43))/(1+$B$44)^5))-$B$19+$B$18)/$B$20 | G44: =((((($F$12*(1+($B$7+(G$43-$B$7)*1/5)))*$B$8)/(1+$B$44)^1)+((($F$12*(1+($B$7+(G$43-$B$7)*1/5))*(1+($B$7+(G$43-$B$7)*2/5)))*$B$8)/(1+$B$44)^2)+((($F$12*(1+($B$7+(G$43-$B$7)*1/5))*(1+($B$7+(G$43-$B$7)*2/5))*(1+($B$7+(G$43-$B$7)*3/5)))*$B$8)/(1+$B$44)^3)+((($F$12*(1+($B$7+(G$43-$B$7)*1/5))*(1+($B$7+(G$43-$B$7)*2/5))*(1+($B$7+(G$43-$B$7)*3/5))*(1+($B$7+(G$43-$B$7)*4/5)))*$B$8)/(1+$B$44)^4)+((($F$12*(1+($B$7+(G$43-$B$7)*1/5))*(1+($B$7+(G$43-$B$7)*2/5))*(1+($B$7+(G$43-$B$7)*3/5))*(1+($B$7+(G$43-$B$7)*4/5))*(1+($B$7+(G$43-$B$7)*5/5)))*$B$8)/(1+$B$44)^5)+((((($F$12*(1+($B$7+(G$43-$B$7)*1/5))*(1+($B$7+(G$43-$B$7)*2/5))*(1+($B$7+(G$43-$B$7)*3/5))*(1+($B$7+(G$43-$B$7)*4/5))*(1+($B$7+(G$43-$B$7)*5/5)))*$B$8)*(1+G$43))/($B$44-G$43))/(1+$B$44)^5))-$B$19+$B$18)/$B$20
B45: 0.09 | C45: =((((($F$12*(1+($B$7+(C$43-$B$7)*1/5)))*$B$8)/(1+$B$45)^1)+((($F$12*(1+($B$7+(C$43-$B$7)*1/5))*(1+($B$7+(C$43-$B$7)*2/5)))*$B$8)/(1+$B$45)^2)+((($F$12*(1+($B$7+(C$43-$B$7)*1/5))*(1+($B$7+(C$43-$B$7)*2/5))*(1+($B$7+(C$43-$B$7)*3/5)))*$B$8)/(1+$B$45)^3)+((($F$12*(1+($B$7+(C$43-$B$7)*1/5))*(1+($B$7+(C$43-$B$7)*2/5))*(1+($B$7+(C$43-$B$7)*3/5))*(1+($B$7+(C$43-$B$7)*4/5)))*$B$8)/(1+$B$45)^4)+((($F$12*(1+($B$7+(C$43-$B$7)*1/5))*(1+($B$7+(C$43-$B$7)*2/5))*(1+($B$7+(C$43-$B$7)*3/5))*(1+($B$7+(C$43-$B$7)*4/5))*(1+($B$7+(C$43-$B$7)*5/5)))*$B$8)/(1+$B$45)^5)+((((($F$12*(1+($B$7+(C$43-$B$7)*1/5))*(1+($B$7+(C$43-$B$7)*2/5))*(1+($B$7+(C$43-$B$7)*3/5))*(1+($B$7+(C$43-$B$7)*4/5))*(1+($B$7+(C$43-$B$7)*5/5)))*$B$8)*(1+C$43))/($B$45-C$43))/(1+$B$45)^5))-$B$19+$B$18)/$B$20 | D45: =((((($F$12*(1+($B$7+(D$43-$B$7)*1/5)))*$B$8)/(1+$B$45)^1)+((($F$12*(1+($B$7+(D$43-$B$7)*1/5))*(1+($B$7+(D$43-$B$7)*2/5)))*$B$8)/(1+$B$45)^2)+((($F$12*(1+($B$7+(D$43-$B$7)*1/5))*(1+($B$7+(D$43-$B$7)*2/5))*(1+($B$7+(D$43-$B$7)*3/5)))*$B$8)/(1+$B$45)^3)+((($F$12*(1+($B$7+(D$43-$B$7)*1/5))*(1+($B$7+(D$43-$B$7)*2/5))*(1+($B$7+(D$43-$B$7)*3/5))*(1+($B$7+(D$43-$B$7)*4/5)))*$B$8)/(1+$B$45)^4)+((($F$12*(1+($B$7+(D$43-$B$7)*1/5))*(1+($B$7+(D$43-$B$7)*2/5))*(1+($B$7+(D$43-$B$7)*3/5))*(1+($B$7+(D$43-$B$7)*4/5))*(1+($B$7+(D$43-$B$7)*5/5)))*$B$8)/(1+$B$45)^5)+((((($F$12*(1+($B$7+(D$43-$B$7)*1/5))*(1+($B$7+(D$43-$B$7)*2/5))*(1+($B$7+(D$43-$B$7)*3/5))*(1+($B$7+(D$43-$B$7)*4/5))*(1+($B$7+(D$43-$B$7)*5/5)))*$B$8)*(1+D$43))/($B$45-D$43))/(1+$B$45)^5))-$B$19+$B$18)/$B$20 | E45: =((((($F$12*(1+($B$7+(E$43-$B$7)*1/5)))*$B$8)/(1+$B$45)^1)+((($F$12*(1+($B$7+(E$43-$B$7)*1/5))*(1+($B$7+(E$43-$B$7)*2/5)))*$B$8)/(1+$B$45)^2)+((($F$12*(1+($B$7+(E$43-$B$7)*1/5))*(1+($B$7+(E$43-$B$7)*2/5))*(1+($B$7+(E$43-$B$7)*3/5)))*$B$8)/(1+$B$45)^3)+((($F$12*(1+($B$7+(E$43-$B$7)*1/5))*(1+($B$7+(E$43-$B$7)*2/5))*(1+($B$7+(E$43-$B$7)*3/5))*(1+($B$7+(E$43-$B$7)*4/5)))*$B$8)/(1+$B$45)^4)+((($F$12*(1+($B$7+(E$43-$B$7)*1/5))*(1+($B$7+(E$43-$B$7)*2/5))*(1+($B$7+(E$43-$B$7)*3/5))*(1+($B$7+(E$43-$B$7)*4/5))*(1+($B$7+(E$43-$B$7)*5/5)))*$B$8)/(1+$B$45)^5)+((((($F$12*(1+($B$7+(E$43-$B$7)*1/5))*(1+($B$7+(E$43-$B$7)*2/5))*(1+($B$7+(E$43-$B$7)*3/5))*(1+($B$7+(E$43-$B$7)*4/5))*(1+($B$7+(E$43-$B$7)*5/5)))*$B$8)*(1+E$43))/($B$45-E$43))/(1+$B$45)^5))-$B$19+$B$18)/$B$20 | F45: =((((($F$12*(1+($B$7+(F$43-$B$7)*1/5)))*$B$8)/(1+$B$45)^1)+((($F$12*(1+($B$7+(F$43-$B$7)*1/5))*(1+($B$7+(F$43-$B$7)*2/5)))*$B$8)/(1+$B$45)^2)+((($F$12*(1+($B$7+(F$43-$B$7)*1/5))*(1+($B$7+(F$43-$B$7)*2/5))*(1+($B$7+(F$43-$B$7)*3/5)))*$B$8)/(1+$B$45)^3)+((($F$12*(1+($B$7+(F$43-$B$7)*1/5))*(1+($B$7+(F$43-$B$7)*2/5))*(1+($B$7+(F$43-$B$7)*3/5))*(1+($B$7+(F$43-$B$7)*4/5)))*$B$8)/(1+$B$45)^4)+((($F$12*(1+($B$7+(F$43-$B$7)*1/5))*(1+($B$7+(F$43-$B$7)*2/5))*(1+($B$7+(F$43-$B$7)*3/5))*(1+($B$7+(F$43-$B$7)*4/5))*(1+($B$7+(F$43-$B$7)*5/5)))*$B$8)/(1+$B$45)^5)+((((($F$12*(1+($B$7+(F$43-$B$7)*1/5))*(1+($B$7+(F$43-$B$7)*2/5))*(1+($B$7+(F$43-$B$7)*3/5))*(1+($B$7+(F$43-$B$7)*4/5))*(1+($B$7+(F$43-$B$7)*5/5)))*$B$8)*(1+F$43))/($B$45-F$43))/(1+$B$45)^5))-$B$19+$B$18)/$B$20 | G45: =((((($F$12*(1+($B$7+(G$43-$B$7)*1/5)))*$B$8)/(1+$B$45)^1)+((($F$12*(1+($B$7+(G$43-$B$7)*1/5))*(1+($B$7+(G$43-$B$7)*2/5)))*$B$8)/(1+$B$45)^2)+((($F$12*(1+($B$7+(G$43-$B$7)*1/5))*(1+($B$7+(G$43-$B$7)*2/5))*(1+($B$7+(G$43-$B$7)*3/5)))*$B$8)/(1+$B$45)^3)+((($F$12*(1+($B$7+(G$43-$B$7)*1/5))*(1+($B$7+(G$43-$B$7)*2/5))*(1+($B$7+(G$43-$B$7)*3/5))*(1+($B$7+(G$43-$B$7)*4/5)))*$B$8)/(1+$B$45)^4)+((($F$12*(1+($B$7+(G$43-$B$7)*1/5))*(1+($B$7+(G$43-$B$7)*2/5))*(1+($B$7+(G$43-$B$7)*3/5))*(1+($B$7+(G$43-$B$7)*4/5))*(1+($B$7+(G$43-$B$7)*5/5)))*$B$8)/(1+$B$45)^5)+((((($F$12*(1+($B$7+(G$43-$B$7)*1/5))*(1+($B$7+(G$43-$B$7)*2/5))*(1+($B$7+(G$43-$B$7)*3/5))*(1+($B$7+(G$43-$B$7)*4/5))*(1+($B$7+(G$43-$B$7)*5/5)))*$B$8)*(1+G$43))/($B$45-G$43))/(1+$B$45)^5))-$B$19+$B$18)/$B$20
B46: 0.1 | C46: =((((($F$12*(1+($B$7+(C$43-$B$7)*1/5)))*$B$8)/(1+$B$46)^1)+((($F$12*(1+($B$7+(C$43-$B$7)*1/5))*(1+($B$7+(C$43-$B$7)*2/5)))*$B$8)/(1+$B$46)^2)+((($F$12*(1+($B$7+(C$43-$B$7)*1/5))*(1+($B$7+(C$43-$B$7)*2/5))*(1+($B$7+(C$43-$B$7)*3/5)))*$B$8)/(1+$B$46)^3)+((($F$12*(1+($B$7+(C$43-$B$7)*1/5))*(1+($B$7+(C$43-$B$7)*2/5))*(1+($B$7+(C$43-$B$7)*3/5))*(1+($B$7+(C$43-$B$7)*4/5)))*$B$8)/(1+$B$46)^4)+((($F$12*(1+($B$7+(C$43-$B$7)*1/5))*(1+($B$7+(C$43-$B$7)*2/5))*(1+($B$7+(C$43-$B$7)*3/5))*(1+($B$7+(C$43-$B$7)*4/5))*(1+($B$7+(C$43-$B$7)*5/5)))*$B$8)/(1+$B$46)^5)+((((($F$12*(1+($B$7+(C$43-$B$7)*1/5))*(1+($B$7+(C$43-$B$7)*2/5))*(1+($B$7+(C$43-$B$7)*3/5))*(1+($B$7+(C$43-$B$7)*4/5))*(1+($B$7+(C$43-$B$7)*5/5)))*$B$8)*(1+C$43))/($B$46-C$43))/(1+$B$46)^5))-$B$19+$B$18)/$B$20 | D46: =((((($F$12*(1+($B$7+(D$43-$B$7)*1/5)))*$B$8)/(1+$B$46)^1)+((($F$12*(1+($B$7+(D$43-$B$7)*1/5))*(1+($B$7+(D$43-$B$7)*2/5)))*$B$8)/(1+$B$46)^2)+((($F$12*(1+($B$7+(D$43-$B$7)*1/5))*(1+($B$7+(D$43-$B$7)*2/5))*(1+($B$7+(D$43-$B$7)*3/5)))*$B$8)/(1+$B$46)^3)+((($F$12*(1+($B$7+(D$43-$B$7)*1/5))*(1+($B$7+(D$43-$B$7)*2/5))*(1+($B$7+(D$43-$B$7)*3/5))*(1+($B$7+(D$43-$B$7)*4/5)))*$B$8)/(1+$B$46)^4)+((($F$12*(1+($B$7+(D$43-$B$7)*1/5))*(1+($B$7+(D$43-$B$7)*2/5))*(1+($B$7+(D$43-$B$7)*3/5))*(1+($B$7+(D$43-$B$7)*4/5))*(1+($B$7+(D$43-$B$7)*5/5)))*$B$8)/(1+$B$46)^5)+((((($F$12*(1+($B$7+(D$43-$B$7)*1/5))*(1+($B$7+(D$43-$B$7)*2/5))*(1+($B$7+(D$43-$B$7)*3/5))*(1+($B$7+(D$43-$B$7)*4/5))*(1+($B$7+(D$43-$B$7)*5/5)))*$B$8)*(1+D$43))/($B$46-D$43))/(1+$B$46)^5))-$B$19+$B$18)/$B$20 | E46: =((((($F$12*(1+($B$7+(E$43-$B$7)*1/5)))*$B$8)/(1+$B$46)^1)+((($F$12*(1+($B$7+(E$43-$B$7)*1/5))*(1+($B$7+(E$43-$B$7)*2/5)))*$B$8)/(1+$B$46)^2)+((($F$12*(1+($B$7+(E$43-$B$7)*1/5))*(1+($B$7+(E$43-$B$7)*2/5))*(1+($B$7+(E$43-$B$7)*3/5)))*$B$8)/(1+$B$46)^3)+((($F$12*(1+($B$7+(E$43-$B$7)*1/5))*(1+($B$7+(E$43-$B$7)*2/5))*(1+($B$7+(E$43-$B$7)*3/5))*(1+($B$7+(E$43-$B$7)*4/5)))*$B$8)/(1+$B$46)^4)+((($F$12*(1+($B$7+(E$43-$B$7)*1/5))*(1+($B$7+(E$43-$B$7)*2/5))*(1+($B$7+(E$43-$B$7)*3/5))*(1+($B$7+(E$43-$B$7)*4/5))*(1+($B$7+(E$43-$B$7)*5/5)))*$B$8)/(1+$B$46)^5)+((((($F$12*(1+($B$7+(E$43-$B$7)*1/5))*(1+($B$7+(E$43-$B$7)*2/5))*(1+($B$7+(E$43-$B$7)*3/5))*(1+($B$7+(E$43-$B$7)*4/5))*(1+($B$7+(E$43-$B$7)*5/5)))*$B$8)*(1+E$43))/($B$46-E$43))/(1+$B$46)^5))-$B$19+$B$18)/$B$20 | F46: =((((($F$12*(1+($B$7+(F$43-$B$7)*1/5)))*$B$8)/(1+$B$46)^1)+((($F$12*(1+($B$7+(F$43-$B$7)*1/5))*(1+($B$7+(F$43-$B$7)*2/5)))*$B$8)/(1+$B$46)^2)+((($F$12*(1+($B$7+(F$43-$B$7)*1/5))*(1+($B$7+(F$43-$B$7)*2/5))*(1+($B$7+(F$43-$B$7)*3/5)))*$B$8)/(1+$B$46)^3)+((($F$12*(1+($B$7+(F$43-$B$7)*1/5))*(1+($B$7+(F$43-$B$7)*2/5))*(1+($B$7+(F$43-$B$7)*3/5))*(1+($B$7+(F$43-$B$7)*4/5)))*$B$8)/(1+$B$46)^4)+((($F$12*(1+($B$7+(F$43-$B$7)*1/5))*(1+($B$7+(F$43-$B$7)*2/5))*(1+($B$7+(F$43-$B$7)*3/5))*(1+($B$7+(F$43-$B$7)*4/5))*(1+($B$7+(F$43-$B$7)*5/5)))*$B$8)/(1+$B$46)^5)+((((($F$12*(1+($B$7+(F$43-$B$7)*1/5))*(1+($B$7+(F$43-$B$7)*2/5))*(1+($B$7+(F$43-$B$7)*3/5))*(1+($B$7+(F$43-$B$7)*4/5))*(1+($B$7+(F$43-$B$7)*5/5)))*$B$8)*(1+F$43))/($B$46-F$43))/(1+$B$46)^5))-$B$19+$B$18)/$B$20 | G46: =((((($F$12*(1+($B$7+(G$43-$B$7)*1/5)))*$B$8)/(1+$B$46)^1)+((($F$12*(1+($B$7+(G$43-$B$7)*1/5))*(1+($B$7+(G$43-$B$7)*2/5)))*$B$8)/(1+$B$46)^2)+((($F$12*(1+($B$7+(G$43-$B$7)*1/5))*(1+($B$7+(G$43-$B$7)*2/5))*(1+($B$7+(G$43-$B$7)*3/5)))*$B$8)/(1+$B$46)^3)+((($F$12*(1+($B$7+(G$43-$B$7)*1/5))*(1+($B$7+(G$43-$B$7)*2/5))*(1+($B$7+(G$43-$B$7)*3/5))*(1+($B$7+(G$43-$B$7)*4/5)))*$B$8)/(1+$B$46)^4)+((($F$12*(1+($B$7+(G$43-$B$7)*1/5))*(1+($B$7+(G$43-$B$7)*2/5))*(1+($B$7+(G$43-$B$7)*3/5))*(1+($B$7+(G$43-$B$7)*4/5))*(1+($B$7+(G$43-$B$7)*5/5)))*$B$8)/(1+$B$46)^5)+((((($F$12*(1+($B$7+(G$43-$B$7)*1/5))*(1+($B$7+(G$43-$B$7)*2/5))*(1+($B$7+(G$43-$B$7)*3/5))*(1+($B$7+(G$43-$B$7)*4/5))*(1+($B$7+(G$43-$B$7)*5/5)))*$B$8)*(1+G$43))/($B$46-G$43))/(1+$B$46)^5))-$B$19+$B$18)/$B$20
...

Sheet ADBE
A1: ADBE — Adobe Inc.
A2: Unlevered DCF | $ in millions except per-share and share count
A4: Assumptions (edit the highlighted cells)
A5: WACC (discount rate) | B5: 0.1
A6: Terminal growth rate | B6: 0.03
A7: Starting revenue growth rate | B7: 0.10527784 | C7: default: most recent YoY revenue growth
A8: Unlevered FCF margin (% of revenue) | B8: 0.39029518 | C8: default: avg of last 2 fiscal years' FCF / revenue
A10: Historical Trend ($ in millions)
A11: Fiscal year | B11: 2021 | C11: 2022 | D11: 2023 | E11: 2024 | F11: 2025
A12: Revenue | B12: 15785 | C12: 17606 | D12: 19409 | E12: 21505 | F12: 23769
A13: Revenue growth % | C13: =C12/B12-1 | D13: =D12/C12-1 | E13: =E12/D12-1 | F13: =F12/E12-1
A14: Free cash flow | B14: 6882 | C14: 7396 | D14: 6942 | E14: 7873 | F14: 9852
A15: FCF margin % | B15: =B14/B12 | C15: =C14/C12 | D15: =D14/D12 | E15: =E14/E12 | F15: =F14/F12
A17: Balance Sheet Actuals — FY2025 ($ in millions)
A18: Cash & equivalents | B18: 5431
A19: Total debt | B19: 6210
A20: Diluted shares outstanding (millions) | B20: 427
A22: 5-Year Projection ($ in millions)
A23: Fiscal year | B23: FY2026E | C23: FY2027E | D23: FY2028E | E23: FY2029E | F23: FY2030E
A24: Revenue growth rate | B24: =$B$7+($B$6-$B$7)*1/5 | C24: =$B$7+($B$6-$B$7)*2/5 | D24: =$B$7+($B$6-$B$7)*3/5 | E24: =$B$7+($B$6-$B$7)*4/5 | F24: =$B$7+($B$6-$B$7)*5/5
A25: Projected revenue | B25: =F12*(1+B24) | C25: =B25*(1+C24) | D25: =C25*(1+D24) | E25: =D25*(1+E24) | F25: =E25*(1+F24)
A26: FCF margin (assumption, held flat) | B26: =$B$8 | C26: =$B$8 | D26: =$B$8 | E26: =$B$8 | F26: =$B$8
A27: Projected unlevered FCF | B27: =B25*B26 | C27: =C25*C26 | D27: =D25*D26 | E27: =E25*E26 | F27: =F25*F26
A28: Discount factor | B28: =1/(1+$B$5)^1 | C28: =1/(1+$B$5)^2 | D28: =1/(1+$B$5)^3 | E28: =1/(1+$B$5)^4 | F28: =1/(1+$B$5)^5
A29: PV of FCF | B29: =B27*B28 | C29: =C27*C28 | D29: =D27*D28 | E29: =E27*E28 | F29: =F27*F28
A31: Terminal Value & Valuation
A32: Terminal value (end of FY2030) | B32: =F27*(1+$B$6)/($B$5-$B$6)
A33: PV of terminal value | B33: =B32*F28
A34: Sum of PV of projected FCFs | B34: =SUM(B29:F29)
A35: Enterprise value | B35: =B33+B34
A36: Less: total debt | B36: =-B19
A37: Plus: cash & equivalents | B37: =B18
A38: Equity value | B38: =B35+B36+B37
A39: Diluted shares outstanding (millions) | B39: =B20
A40: Implied value per share | B40: =B38/B39
A42: Sensitivity: Implied Value/Share (WACC x Terminal Growth)
B43: WACC \ Term. g | C43: 0.02 | D43: 0.025 | E43: 0.03 | F43: 0.035 | G43: 0.04
B44: 0.08 | C44: =((((($F$12*(1+($B$7+(C$43-$B$7)*1/5)))*$B$8)/(1+$B$44)^1)+((($F$12*(1+($B$7+(C$43-$B$7)*1/5))*(1+($B$7+(C$43-$B$7)*2/5)))*$B$8)/(1+$B$44)^2)+((($F$12*(1+($B$7+(C$43-$B$7)*1/5))*(1+($B$7+(C$43-$B$7)*2/5))*(1+($B$7+(C$43-$B$7)*3/5)))*$B$8)/(1+$B$44)^3)+((($F$12*(1+($B$7+(C$43-$B$7)*1/5))*(1+($B$7+(C$43-$B$7)*2/5))*(1+($B$7+(C$43-$B$7)*3/5))*(1+($B$7+(C$43-$B$7)*4/5)))*$B$8)/(1+$B$44)^4)+((($F$12*(1+($B$7+(C$43-$B$7)*1/5))*(1+($B$7+(C$43-$B$7)*2/5))*(1+($B$7+(C$43-$B$7)*3/5))*(1+($B$7+(C$43-$B$7)*4/5))*(1+($B$7+(C$43-$B$7)*5/5)))*$B$8)/(1+$B$44)^5)+((((($F$12*(1+($B$7+(C$43-$B$7)*1/5))*(1+($B$7+(C$43-$B$7)*2/5))*(1+($B$7+(C$43-$B$7)*3/5))*(1+($B$7+(C$43-$B$7)*4/5))*(1+($B$7+(C$43-$B$7)*5/5)))*$B$8)*(1+C$43))/($B$44-C$43))/(1+$B$44)^5))-$B$19+$B$18)/$B$20 | D44: =((((($F$12*(1+($B$7+(D$43-$B$7)*1/5)))*$B$8)/(1+$B$44)^1)+((($F$12*(1+($B$7+(D$43-$B$7)*1/5))*(1+($B$7+(D$43-$B$7)*2/5)))*$B$8)/(1+$B$44)^2)+((($F$12*(1+($B$7+(D$43-$B$7)*1/5))*(1+($B$7+(D$43-$B$7)*2/5))*(1+($B$7+(D$43-$B$7)*3/5)))*$B$8)/(1+$B$44)^3)+((($F$12*(1+($B$7+(D$43-$B$7)*1/5))*(1+($B$7+(D$43-$B$7)*2/5))*(1+($B$7+(D$43-$B$7)*3/5))*(1+($B$7+(D$43-$B$7)*4/5)))*$B$8)/(1+$B$44)^4)+((($F$12*(1+($B$7+(D$43-$B$7)*1/5))*(1+($B$7+(D$43-$B$7)*2/5))*(1+($B$7+(D$43-$B$7)*3/5))*(1+($B$7+(D$43-$B$7)*4/5))*(1+($B$7+(D$43-$B$7)*5/5)))*$B$8)/(1+$B$44)^5)+((((($F$12*(1+($B$7+(D$43-$B$7)*1/5))*(1+($B$7+(D$43-$B$7)*2/5))*(1+($B$7+(D$43-$B$7)*3/5))*(1+($B$7+(D$43-$B$7)*4/5))*(1+($B$7+(D$43-$B$7)*5/5)))*$B$8)*(1+D$43))/($B$44-D$43))/(1+$B$44)^5))-$B$19+$B$18)/$B$20 | E44: =((((($F$12*(1+($B$7+(E$43-$B$7)*1/5)))*$B$8)/(1+$B$44)^1)+((($F$12*(1+($B$7+(E$43-$B$7)*1/5))*(1+($B$7+(E$43-$B$7)*2/5)))*$B$8)/(1+$B$44)^2)+((($F$12*(1+($B$7+(E$43-$B$7)*1/5))*(1+($B$7+(E$43-$B$7)*2/5))*(1+($B$7+(E$43-$B$7)*3/5)))*$B$8)/(1+$B$44)^3)+((($F$12*(1+($B$7+(E$43-$B$7)*1/5))*(1+($B$7+(E$43-$B$7)*2/5))*(1+($B$7+(E$43-$B$7)*3/5))*(1+($B$7+(E$43-$B$7)*4/5)))*$B$8)/(1+$B$44)^4)+((($F$12*(1+($B$7+(E$43-$B$7)*1/5))*(1+($B$7+(E$43-$B$7)*2/5))*(1+($B$7+(E$43-$B$7)*3/5))*(1+($B$7+(E$43-$B$7)*4/5))*(1+($B$7+(E$43-$B$7)*5/5)))*$B$8)/(1+$B$44)^5)+((((($F$12*(1+($B$7+(E$43-$B$7)*1/5))*(1+($B$7+(E$43-$B$7)*2/5))*(1+($B$7+(E$43-$B$7)*3/5))*(1+($B$7+(E$43-$B$7)*4/5))*(1+($B$7+(E$43-$B$7)*5/5)))*$B$8)*(1+E$43))/($B$44-E$43))/(1+$B$44)^5))-$B$19+$B$18)/$B$20 | F44: =((((($F$12*(1+($B$7+(F$43-$B$7)*1/5)))*$B$8)/(1+$B$44)^1)+((($F$12*(1+($B$7+(F$43-$B$7)*1/5))*(1+($B$7+(F$43-$B$7)*2/5)))*$B$8)/(1+$B$44)^2)+((($F$12*(1+($B$7+(F$43-$B$7)*1/5))*(1+($B$7+(F$43-$B$7)*2/5))*(1+($B$7+(F$43-$B$7)*3/5)))*$B$8)/(1+$B$44)^3)+((($F$12*(1+($B$7+(F$43-$B$7)*1/5))*(1+($B$7+(F$43-$B$7)*2/5))*(1+($B$7+(F$43-$B$7)*3/5))*(1+($B$7+(F$43-$B$7)*4/5)))*$B$8)/(1+$B$44)^4)+((($F$12*(1+($B$7+(F$43-$B$7)*1/5))*(1+($B$7+(F$43-$B$7)*2/5))*(1+($B$7+(F$43-$B$7)*3/5))*(1+($B$7+(F$43-$B$7)*4/5))*(1+($B$7+(F$43-$B$7)*5/5)))*$B$8)/(1+$B$44)^5)+((((($F$12*(1+($B$7+(F$43-$B$7)*1/5))*(1+($B$7+(F$43-$B$7)*2/5))*(1+($B$7+(F$43-$B$7)*3/5))*(1+($B$7+(F$43-$B$7)*4/5))*(1+($B$7+(F$43-$B$7)*5/5)))*$B$8)*(1+F$43))/($B$44-F$43))/(1+$B$44)^5))-$B$19+$B$18)/$B$20 | G44: =((((($F$12*(1+($B$7+(G$43-$B$7)*1/5)))*$B$8)/(1+$B$44)^1)+((($F$12*(1+($B$7+(G$43-$B$7)*1/5))*(1+($B$7+(G$43-$B$7)*2/5)))*$B$8)/(1+$B$44)^2)+((($F$12*(1+($B$7+(G$43-$B$7)*1/5))*(1+($B$7+(G$43-$B$7)*2/5))*(1+($B$7+(G$43-$B$7)*3/5)))*$B$8)/(1+$B$44)^3)+((($F$12*(1+($B$7+(G$43-$B$7)*1/5))*(1+($B$7+(G$43-$B$7)*2/5))*(1+($B$7+(G$43-$B$7)*3/5))*(1+($B$7+(G$43-$B$7)*4/5)))*$B$8)/(1+$B$44)^4)+((($F$12*(1+($B$7+(G$43-$B$7)*1/5))*(1+($B$7+(G$43-$B$7)*2/5))*(1+($B$7+(G$43-$B$7)*3/5))*(1+($B$7+(G$43-$B$7)*4/5))*(1+($B$7+(G$43-$B$7)*5/5)))*$B$8)/(1+$B$44)^5)+((((($F$12*(1+($B$7+(G$43-$B$7)*1/5))*(1+($B$7+(G$43-$B$7)*2/5))*(1+($B$7+(G$43-$B$7)*3/5))*(1+($B$7+(G$43-$B$7)*4/5))*(1+($B$7+(G$43-$B$7)*5/5)))*$B$8)*(1+G$43))/($B$44-G$43))/(1+$B$44)^5))-$B$19+$B$18)/$B$20
B45: 0.09 | C45: =((((($F$12*(1+($B$7+(C$43-$B$7)*1/5)))*$B$8)/(1+$B$45)^1)+((($F$12*(1+($B$7+(C$43-$B$7)*1/5))*(1+($B$7+(C$43-$B$7)*2/5)))*$B$8)/(1+$B$45)^2)+((($F$12*(1+($B$7+(C$43-$B$7)*1/5))*(1+($B$7+(C$43-$B$7)*2/5))*(1+($B$7+(C$43-$B$7)*3/5)))*$B$8)/(1+$B$45)^3)+((($F$12*(1+($B$7+(C$43-$B$7)*1/5))*(1+($B$7+(C$43-$B$7)*2/5))*(1+($B$7+(C$43-$B$7)*3/5))*(1+($B$7+(C$43-$B$7)*4/5)))*$B$8)/(1+$B$45)^4)+((($F$12*(1+($B$7+(C$43-$B$7)*1/5))*(1+($B$7+(C$43-$B$7)*2/5))*(1+($B$7+(C$43-$B$7)*3/5))*(1+($B$7+(C$43-$B$7)*4/5))*(1+($B$7+(C$43-$B$7)*5/5)))*$B$8)/(1+$B$45)^5)+((((($F$12*(1+($B$7+(C$43-$B$7)*1/5))*(1+($B$7+(C$43-$B$7)*2/5))*(1+($B$7+(C$43-$B$7)*3/5))*(1+($B$7+(C$43-$B$7)*4/5))*(1+($B$7+(C$43-$B$7)*5/5)))*$B$8)*(1+C$43))/($B$45-C$43))/(1+$B$45)^5))-$B$19+$B$18)/$B$20 | D45: =((((($F$12*(1+($B$7+(D$43-$B$7)*1/5)))*$B$8)/(1+$B$45)^1)+((($F$12*(1+($B$7+(D$43-$B$7)*1/5))*(1+($B$7+(D$43-$B$7)*2/5)))*$B$8)/(1+$B$45)^2)+((($F$12*(1+($B$7+(D$43-$B$7)*1/5))*(1+($B$7+(D$43-$B$7)*2/5))*(1+($B$7+(D$43-$B$7)*3/5)))*$B$8)/(1+$B$45)^3)+((($F$12*(1+($B$7+(D$43-$B$7)*1/5))*(1+($B$7+(D$43-$B$7)*2/5))*(1+($B$7+(D$43-$B$7)*3/5))*(1+($B$7+(D$43-$B$7)*4/5)))*$B$8)/(1+$B$45)^4)+((($F$12*(1+($B$7+(D$43-$B$7)*1/5))*(1+($B$7+(D$43-$B$7)*2/5))*(1+($B$7+(D$43-$B$7)*3/5))*(1+($B$7+(D$43-$B$7)*4/5))*(1+($B$7+(D$43-$B$7)*5/5)))*$B$8)/(1+$B$45)^5)+((((($F$12*(1+($B$7+(D$43-$B$7)*1/5))*(1+($B$7+(D$43-$B$7)*2/5))*(1+($B$7+(D$43-$B$7)*3/5))*(1+($B$7+(D$43-$B$7)*4/5))*(1+($B$7+(D$43-$B$7)*5/5)))*$B$8)*(1+D$43))/($B$45-D$43))/(1+$B$45)^5))-$B$19+$B$18)/$B$20 | E45: =((((($F$12*(1+($B$7+(E$43-$B$7)*1/5)))*$B$8)/(1+$B$45)^1)+((($F$12*(1+($B$7+(E$43-$B$7)*1/5))*(1+($B$7+(E$43-$B$7)*2/5)))*$B$8)/(1+$B$45)^2)+((($F$12*(1+($B$7+(E$43-$B$7)*1/5))*(1+($B$7+(E$43-$B$7)*2/5))*(1+($B$7+(E$43-$B$7)*3/5)))*$B$8)/(1+$B$45)^3)+((($F$12*(1+($B$7+(E$43-$B$7)*1/5))*(1+($B$7+(E$43-$B$7)*2/5))*(1+($B$7+(E$43-$B$7)*3/5))*(1+($B$7+(E$43-$B$7)*4/5)))*$B$8)/(1+$B$45)^4)+((($F$12*(1+($B$7+(E$43-$B$7)*1/5))*(1+($B$7+(E$43-$B$7)*2/5))*(1+($B$7+(E$43-$B$7)*3/5))*(1+($B$7+(E$43-$B$7)*4/5))*(1+($B$7+(E$43-$B$7)*5/5)))*$B$8)/(1+$B$45)^5)+((((($F$12*(1+($B$7+(E$43-$B$7)*1/5))*(1+($B$7+(E$43-$B$7)*2/5))*(1+($B$7+(E$43-$B$7)*3/5))*(1+($B$7+(E$43-$B$7)*4/5))*(1+($B$7+(E$43-$B$7)*5/5)))*$B$8)*(1+E$43))/($B$45-E$43))/(1+$B$45)^5))-$B$19+$B$18)/$B$20 | F45: =((((($F$12*(1+($B$7+(F$43-$B$7)*1/5)))*$B$8)/(1+$B$45)^1)+((($F$12*(1+($B$7+(F$43-$B$7)*1/5))*(1+($B$7+(F$43-$B$7)*2/5)))*$B$8)/(1+$B$45)^2)+((($F$12*(1+($B$7+(F$43-$B$7)*1/5))*(1+($B$7+(F$43-$B$7)*2/5))*(1+($B$7+(F$43-$B$7)*3/5)))*$B$8)/(1+$B$45)^3)+((($F$12*(1+($B$7+(F$43-$B$7)*1/5))*(1+($B$7+(F$43-$B$7)*2/5))*(1+($B$7+(F$43-$B$7)*3/5))*(1+($B$7+(F$43-$B$7)*4/5)))*$B$8)/(1+$B$45)^4)+((($F$12*(1+($B$7+(F$43-$B$7)*1/5))*(1+($B$7+(F$43-$B$7)*2/5))*(1+($B$7+(F$43-$B$7)*3/5))*(1+($B$7+(F$43-$B$7)*4/5))*(1+($B$7+(F$43-$B$7)*5/5)))*$B$8)/(1+$B$45)^5)+((((($F$12*(1+($B$7+(F$43-$B$7)*1/5))*(1+($B$7+(F$43-$B$7)*2/5))*(1+($B$7+(F$43-$B$7)*3/5))*(1+($B$7+(F$43-$B$7)*4/5))*(1+($B$7+(F$43-$B$7)*5/5)))*$B$8)*(1+F$43))/($B$45-F$43))/(1+$B$45)^5))-$B$19+$B$18)/$B$20 | G45: =((((($F$12*(1+($B$7+(G$43-$B$7)*1/5)))*$B$8)/(1+$B$45)^1)+((($F$12*(1+($B$7+(G$43-$B$7)*1/5))*(1+($B$7+(G$43-$B$7)*2/5)))*$B$8)/(1+$B$45)^2)+((($F$12*(1+($B$7+(G$43-$B$7)*1/5))*(1+($B$7+(G$43-$B$7)*2/5))*(1+($B$7+(G$43-$B$7)*3/5)))*$B$8)/(1+$B$45)^3)+((($F$12*(1+($B$7+(G$43-$B$7)*1/5))*(1+($B$7+(G$43-$B$7)*2/5))*(1+($B$7+(G$43-$B$7)*3/5))*(1+($B$7+(G$43-$B$7)*4/5)))*$B$8)/(1+$B$45)^4)+((($F$12*(1+($B$7+(G$43-$B$7)*1/5))*(1+($B$7+(G$43-$B$7)*2/5))*(1+($B$7+(G$43-$B$7)*3/5))*(1+($B$7+(G$43-$B$7)*4/5))*(1+($B$7+(G$43-$B$7)*5/5)))*$B$8)/(1+$B$45)^5)+((((($F$12*(1+($B$7+(G$43-$B$7)*1/5))*(1+($B$7+(G$43-$B$7)*2/5))*(1+($B$7+(G$43-$B$7)*3/5))*(1+($B$7+(G$43-$B$7)*4/5))*(1+($B$7+(G$43-$B$7)*5/5)))*$B$8)*(1+G$43))/($B$45-G$43))/(1+$B$45)^5))-$B$19+$B$18)/$B$20
B46: 0.1 | C46: =((((($F$12*(1+($B$7+(C$43-$B$7)*1/5)))*$B$8)/(1+$B$46)^1)+((($F$12*(1+($B$7+(C$43-$B$7)*1/5))*(1+($B$7+(C$43-$B$7)*2/5)))*$B$8)/(1+$B$46)^2)+((($F$12*(1+($B$7+(C$43-$B$7)*1/5))*(1+($B$7+(C$43-$B$7)*2/5))*(1+($B$7+(C$43-$B$7)*3/5)))*$B$8)/(1+$B$46)^3)+((($F$12*(1+($B$7+(C$43-$B$7)*1/5))*(1+($B$7+(C$43-$B$7)*2/5))*(1+($B$7+(C$43-$B$7)*3/5))*(1+($B$7+(C$43-$B$7)*4/5)))*$B$8)/(1+$B$46)^4)+((($F$12*(1+($B$7+(C$43-$B$7)*1/5))*(1+($B$7+(C$43-$B$7)*2/5))*(1+($B$7+(C$43-$B$7)*3/5))*(1+($B$7+(C$43-$B$7)*4/5))*(1+($B$7+(C$43-$B$7)*5/5)))*$B$8)/(1+$B$46)^5)+((((($F$12*(1+($B$7+(C$43-$B$7)*1/5))*(1+($B$7+(C$43-$B$7)*2/5))*(1+($B$7+(C$43-$B$7)*3/5))*(1+($B$7+(C$43-$B$7)*4/5))*(1+($B$7+(C$43-$B$7)*5/5)))*$B$8)*(1+C$43))/($B$46-C$43))/(1+$B$46)^5))-$B$19+$B$18)/$B$20 | D46: =((((($F$12*(1+($B$7+(D$43-$B$7)*1/5)))*$B$8)/(1+$B$46)^1)+((($F$12*(1+($B$7+(D$43-$B$7)*1/5))*(1+($B$7+(D$43-$B$7)*2/5)))*$B$8)/(1+$B$46)^2)+((($F$12*(1+($B$7+(D$43-$B$7)*1/5))*(1+($B$7+(D$43-$B$7)*2/5))*(1+($B$7+(D$43-$B$7)*3/5)))*$B$8)/(1+$B$46)^3)+((($F$12*(1+($B$7+(D$43-$B$7)*1/5))*(1+($B$7+(D$43-$B$7)*2/5))*(1+($B$7+(D$43-$B$7)*3/5))*(1+($B$7+(D$43-$B$7)*4/5)))*$B$8)/(1+$B$46)^4)+((($F$12*(1+($B$7+(D$43-$B$7)*1/5))*(1+($B$7+(D$43-$B$7)*2/5))*(1+($B$7+(D$43-$B$7)*3/5))*(1+($B$7+(D$43-$B$7)*4/5))*(1+($B$7+(D$43-$B$7)*5/5)))*$B$8)/(1+$B$46)^5)+((((($F$12*(1+($B$7+(D$43-$B$7)*1/5))*(1+($B$7+(D$43-$B$7)*2/5))*(1+($B$7+(D$43-$B$7)*3/5))*(1+($B$7+(D$43-$B$7)*4/5))*(1+($B$7+(D$43-$B$7)*5/5)))*$B$8)*(1+D$43))/($B$46-D$43))/(1+$B$46)^5))-$B$19+$B$18)/$B$20 | E46: =((((($F$12*(1+($B$7+(E$43-$B$7)*1/5)))*$B$8)/(1+$B$46)^1)+((($F$12*(1+($B$7+(E$43-$B$7)*1/5))*(1+($B$7+(E$43-$B$7)*2/5)))*$B$8)/(1+$B$46)^2)+((($F$12*(1+($B$7+(E$43-$B$7)*1/5))*(1+($B$7+(E$43-$B$7)*2/5))*(1+($B$7+(E$43-$B$7)*3/5)))*$B$8)/(1+$B$46)^3)+((($F$12*(1+($B$7+(E$43-$B$7)*1/5))*(1+($B$7+(E$43-$B$7)*2/5))*(1+($B$7+(E$43-$B$7)*3/5))*(1+($B$7+(E$43-$B$7)*4/5)))*$B$8)/(1+$B$46)^4)+((($F$12*(1+($B$7+(E$43-$B$7)*1/5))*(1+($B$7+(E$43-$B$7)*2/5))*(1+($B$7+(E$43-$B$7)*3/5))*(1+($B$7+(E$43-$B$7)*4/5))*(1+($B$7+(E$43-$B$7)*5/5)))*$B$8)/(1+$B$46)^5)+((((($F$12*(1+($B$7+(E$43-$B$7)*1/5))*(1+($B$7+(E$43-$B$7)*2/5))*(1+($B$7+(E$43-$B$7)*3/5))*(1+($B$7+(E$43-$B$7)*4/5))*(1+($B$7+(E$43-$B$7)*5/5)))*$B$8)*(1+E$43))/($B$46-E$43))/(1+$B$46)^5))-$B$19+$B$18)/$B$20 | F46: =((((($F$12*(1+($B$7+(F$43-$B$7)*1/5)))*$B$8)/(1+$B$46)^1)+((($F$12*(1+($B$7+(F$43-$B$7)*1/5))*(1+($B$7+(F$43-$B$7)*2/5)))*$B$8)/(1+$B$46)^2)+((($F$12*(1+($B$7+(F$43-$B$7)*1/5))*(1+($B$7+(F$43-$B$7)*2/5))*(1+($B$7+(F$43-$B$7)*3/5)))*$B$8)/(1+$B$46)^3)+((($F$12*(1+($B$7+(F$43-$B$7)*1/5))*(1+($B$7+(F$43-$B$7)*2/5))*(1+($B$7+(F$43-$B$7)*3/5))*(1+($B$7+(F$43-$B$7)*4/5)))*$B$8)/(1+$B$46)^4)+((($F$12*(1+($B$7+(F$43-$B$7)*1/5))*(1+($B$7+(F$43-$B$7)*2/5))*(1+($B$7+(F$43-$B$7)*3/5))*(1+($B$7+(F$43-$B$7)*4/5))*(1+($B$7+(F$43-$B$7)*5/5)))*$B$8)/(1+$B$46)^5)+((((($F$12*(1+($B$7+(F$43-$B$7)*1/5))*(1+($B$7+(F$43-$B$7)*2/5))*(1+($B$7+(F$43-$B$7)*3/5))*(1+($B$7+(F$43-$B$7)*4/5))*(1+($B$7+(F$43-$B$7)*5/5)))*$B$8)*(1+F$43))/($B$46-F$43))/(1+$B$46)^5))-$B$19+$B$18)/$B$20 | G46: =((((($F$12*(1+($B$7+(G$43-$B$7)*1/5)))*$B$8)/(1+$B$46)^1)+((($F$12*(1+($B$7+(G$43-$B$7)*1/5))*(1+($B$7+(G$43-$B$7)*2/5)))*$B$8)/(1+$B$46)^2)+((($F$12*(1+($B$7+(G$43-$B$7)*1/5))*(1+($B$7+(G$43-$B$7)*2/5))*(1+($B$7+(G$43-$B$7)*3/5)))*$B$8)/(1+$B$46)^3)+((($F$12*(1+($B$7+(G$43-$B$7)*1/5))*(1+($B$7+(G$43-$B$7)*2/5))*(1+($B$7+(G$43-$B$7)*3/5))*(1+($B$7+(G$43-$B$7)*4/5)))*$B$8)/(1+$B$46)^4)+((($F$12*(1+($B$7+(G$43-$B$7)*1/5))*(1+($B$7+(G$43-$B$7)*2/5))*(1+($B$7+(G$43-$B$7)*3/5))*(1+($B$7+(G$43-$B$7)*4/5))*(1+($B$7+(G$43-$B$7)*5/5)))*$B$8)/(1+$B$46)^5)+((((($F$12*(1+($B$7+(G$43-$B$7)*1/5))*(1+($B$7+(G$43-$B$7)*2/5))*(1+($B$7+(G$43-$B$7)*3/5))*(1+($B$7+(G$43-$B$7)*4/5))*(1+($B$7+(G$43-$B$7)*5/5)))*$B$8)*(1+G$43))/($B$46-G$43))/(1+$B$46)^5))-$B$19+$B$18)/$B$20
...

Sheet NOW
A1: NOW — ServiceNow, Inc.
A2: Unlevered DCF | $ in millions except per-share and share count
A4: Assumptions (edit the highlighted cells)
A5: WACC (discount rate) | B5: 0.1
A6: Terminal growth rate | B6: 0.03
A7: Starting revenue growth rate | B7: 0.20884924 | C7: default: most recent YoY revenue growth
A8: Unlevered FCF margin (% of revenue) | B8: 0.32776849 | C8: default: avg of last 2 fiscal years' FCF / revenue
A10: Historical Trend ($ in millions)
A11: Fiscal year | B11: 2021 | C11: 2022 | D11: 2023 | E11: 2024 | F11: 2025
A12: Revenue | B12: 5896 | C12: 7245 | D12: 8971 | E12: 10984 | F12: 13278
A13: Revenue growth % | C13: =C12/B12-1 | D13: =D12/C12-1 | E13: =E12/D12-1 | F13: =F12/E12-1
A14: Free cash flow | B14: 1799 | C14: 2173 | D14: 2704 | E14: 3415 | F14: 4576
A15: FCF margin % | B15: =B14/B12 | C15: =C14/C12 | D15: =D14/D12 | E15: =E14/E12 | F15: =F14/F12
A17: Balance Sheet Actuals — FY2025 ($ in millions)
A18: Cash & equivalents | B18: 3726
A19: Total debt | B19: 1491
A20: Diluted shares outstanding (millions) | B20: 1046.691
A22: 5-Year Projection ($ in millions)
A23: Fiscal year | B23: FY2026E | C23: FY2027E | D23: FY2028E | E23: FY2029E | F23: FY2030E
A24: Revenue growth rate | B24: =$B$7+($B$6-$B$7)*1/5 | C24: =$B$7+($B$6-$B$7)*2/5 | D24: =$B$7+($B$6-$B$7)*3/5 | E24: =$B$7+($B$6-$B$7)*4/5 | F24: =$B$7+($B$6-$B$7)*5/5
A25: Projected revenue | B25: =F12*(1+B24) | C25: =B25*(1+C24) | D25: =C25*(1+D24) | E25: =D25*(1+E24) | F25: =E25*(1+F24)
A26: FCF margin (assumption, held flat) | B26: =$B$8 | C26: =$B$8 | D26: =$B$8 | E26: =$B$8 | F26: =$B$8
A27: Projected unlevered FCF | B27: =B25*B26 | C27: =C25*C26 | D27: =D25*D26 | E27: =E25*E26 | F27: =F25*F26
A28: Discount factor | B28: =1/(1+$B$5)^1 | C28: =1/(1+$B$5)^2 | D28: =1/(1+$B$5)^3 | E28: =1/(1+$B$5)^4 | F28: =1/(1+$B$5)^5
A29: PV of FCF | B29: =B27*B28 | C29: =C27*C28 | D29: =D27*D28 | E29: =E27*E28 | F29: =F27*F28
A31: Terminal Value & Valuation
A32: Terminal value (end of FY2030) | B32: =F27*(1+$B$6)/($B$5-$B$6)
A33: PV of terminal value | B33: =B32*F28
A34: Sum of PV of projected FCFs | B34: =SUM(B29:F29)
A35: Enterprise value | B35: =B33+B34
A36: Less: total debt | B36: =-B19
A37: Plus: cash & equivalents | B37: =B18
A38: Equity value | B38: =B35+B36+B37
A39: Diluted shares outstanding (millions) | B39: =B20
A40: Implied value per share | B40: =B38/B39
A42: Sensitivity: Implied Value/Share (WACC x Terminal Growth)
B43: WACC \ Term. g | C43: 0.02 | D43: 0.025 | E43: 0.03 | F43: 0.035 | G43: 0.04
B44: 0.08 | C44: =((((($F$12*(1+($B$7+(C$43-$B$7)*1/5)))*$B$8)/(1+$B$44)^1)+((($F$12*(1+($B$7+(C$43-$B$7)*1/5))*(1+($B$7+(C$43-$B$7)*2/5)))*$B$8)/(1+$B$44)^2)+((($F$12*(1+($B$7+(C$43-$B$7)*1/5))*(1+($B$7+(C$43-$B$7)*2/5))*(1+($B$7+(C$43-$B$7)*3/5)))*$B$8)/(1+$B$44)^3)+((($F$12*(1+($B$7+(C$43-$B$7)*1/5))*(1+($B$7+(C$43-$B$7)*2/5))*(1+($B$7+(C$43-$B$7)*3/5))*(1+($B$7+(C$43-$B$7)*4/5)))*$B$8)/(1+$B$44)^4)+((($F$12*(1+($B$7+(C$43-$B$7)*1/5))*(1+($B$7+(C$43-$B$7)*2/5))*(1+($B$7+(C$43-$B$7)*3/5))*(1+($B$7+(C$43-$B$7)*4/5))*(1+($B$7+(C$43-$B$7)*5/5)))*$B$8)/(1+$B$44)^5)+((((($F$12*(1+($B$7+(C$43-$B$7)*1/5))*(1+($B$7+(C$43-$B$7)*2/5))*(1+($B$7+(C$43-$B$7)*3/5))*(1+($B$7+(C$43-$B$7)*4/5))*(1+($B$7+(C$43-$B$7)*5/5)))*$B$8)*(1+C$43))/($B$44-C$43))/(1+$B$44)^5))-$B$19+$B$18)/$B$20 | D44: =((((($F$12*(1+($B$7+(D$43-$B$7)*1/5)))*$B$8)/(1+$B$44)^1)+((($F$12*(1+($B$7+(D$43-$B$7)*1/5))*(1+($B$7+(D$43-$B$7)*2/5)))*$B$8)/(1+$B$44)^2)+((($F$12*(1+($B$7+(D$43-$B$7)*1/5))*(1+($B$7+(D$43-$B$7)*2/5))*(1+($B$7+(D$43-$B$7)*3/5)))*$B$8)/(1+$B$44)^3)+((($F$12*(1+($B$7+(D$43-$B$7)*1/5))*(1+($B$7+(D$43-$B$7)*2/5))*(1+($B$7+(D$43-$B$7)*3/5))*(1+($B$7+(D$43-$B$7)*4/5)))*$B$8)/(1+$B$44)^4)+((($F$12*(1+($B$7+(D$43-$B$7)*1/5))*(1+($B$7+(D$43-$B$7)*2/5))*(1+($B$7+(D$43-$B$7)*3/5))*(1+($B$7+(D$43-$B$7)*4/5))*(1+($B$7+(D$43-$B$7)*5/5)))*$B$8)/(1+$B$44)^5)+((((($F$12*(1+($B$7+(D$43-$B$7)*1/5))*(1+($B$7+(D$43-$B$7)*2/5))*(1+($B$7+(D$43-$B$7)*3/5))*(1+($B$7+(D$43-$B$7)*4/5))*(1+($B$7+(D$43-$B$7)*5/5)))*$B$8)*(1+D$43))/($B$44-D$43))/(1+$B$44)^5))-$B$19+$B$18)/$B$20 | E44: =((((($F$12*(1+($B$7+(E$43-$B$7)*1/5)))*$B$8)/(1+$B$44)^1)+((($F$12*(1+($B$7+(E$43-$B$7)*1/5))*(1+($B$7+(E$43-$B$7)*2/5)))*$B$8)/(1+$B$44)^2)+((($F$12*(1+($B$7+(E$43-$B$7)*1/5))*(1+($B$7+(E$43-$B$7)*2/5))*(1+($B$7+(E$43-$B$7)*3/5)))*$B$8)/(1+$B$44)^3)+((($F$12*(1+($B$7+(E$43-$B$7)*1/5))*(1+($B$7+(E$43-$B$7)*2/5))*(1+($B$7+(E$43-$B$7)*3/5))*(1+($B$7+(E$43-$B$7)*4/5)))*$B$8)/(1+$B$44)^4)+((($F$12*(1+($B$7+(E$43-$B$7)*1/5))*(1+($B$7+(E$43-$B$7)*2/5))*(1+($B$7+(E$43-$B$7)*3/5))*(1+($B$7+(E$43-$B$7)*4/5))*(1+($B$7+(E$43-$B$7)*5/5)))*$B$8)/(1+$B$44)^5)+((((($F$12*(1+($B$7+(E$43-$B$7)*1/5))*(1+($B$7+(E$43-$B$7)*2/5))*(1+($B$7+(E$43-$B$7)*3/5))*(1+($B$7+(E$43-$B$7)*4/5))*(1+($B$7+(E$43-$B$7)*5/5)))*$B$8)*(1+E$43))/($B$44-E$43))/(1+$B$44)^5))-$B$19+$B$18)/$B$20 | F44: =((((($F$12*(1+($B$7+(F$43-$B$7)*1/5)))*$B$8)/(1+$B$44)^1)+((($F$12*(1+($B$7+(F$43-$B$7)*1/5))*(1+($B$7+(F$43-$B$7)*2/5)))*$B$8)/(1+$B$44)^2)+((($F$12*(1+($B$7+(F$43-$B$7)*1/5))*(1+($B$7+(F$43-$B$7)*2/5))*(1+($B$7+(F$43-$B$7)*3/5)))*$B$8)/(1+$B$44)^3)+((($F$12*(1+($B$7+(F$43-$B$7)*1/5))*(1+($B$7+(F$43-$B$7)*2/5))*(1+($B$7+(F$43-$B$7)*3/5))*(1+($B$7+(F$43-$B$7)*4/5)))*$B$8)/(1+$B$44)^4)+((($F$12*(1+($B$7+(F$43-$B$7)*1/5))*(1+($B$7+(F$43-$B$7)*2/5))*(1+($B$7+(F$43-$B$7)*3/5))*(1+($B$7+(F$43-$B$7)*4/5))*(1+($B$7+(F$43-$B$7)*5/5)))*$B$8)/(1+$B$44)^5)+((((($F$12*(1+($B$7+(F$43-$B$7)*1/5))*(1+($B$7+(F$43-$B$7)*2/5))*(1+($B$7+(F$43-$B$7)*3/5))*(1+($B$7+(F$43-$B$7)*4/5))*(1+($B$7+(F$43-$B$7)*5/5)))*$B$8)*(1+F$43))/($B$44-F$43))/(1+$B$44)^5))-$B$19+$B$18)/$B$20 | G44: =((((($F$12*(1+($B$7+(G$43-$B$7)*1/5)))*$B$8)/(1+$B$44)^1)+((($F$12*(1+($B$7+(G$43-$B$7)*1/5))*(1+($B$7+(G$43-$B$7)*2/5)))*$B$8)/(1+$B$44)^2)+((($F$12*(1+($B$7+(G$43-$B$7)*1/5))*(1+($B$7+(G$43-$B$7)*2/5))*(1+($B$7+(G$43-$B$7)*3/5)))*$B$8)/(1+$B$44)^3)+((($F$12*(1+($B$7+(G$43-$B$7)*1/5))*(1+($B$7+(G$43-$B$7)*2/5))*(1+($B$7+(G$43-$B$7)*3/5))*(1+($B$7+(G$43-$B$7)*4/5)))*$B$8)/(1+$B$44)^4)+((($F$12*(1+($B$7+(G$43-$B$7)*1/5))*(1+($B$7+(G$43-$B$7)*2/5))*(1+($B$7+(G$43-$B$7)*3/5))*(1+($B$7+(G$43-$B$7)*4/5))*(1+($B$7+(G$43-$B$7)*5/5)))*$B$8)/(1+$B$44)^5)+((((($F$12*(1+($B$7+(G$43-$B$7)*1/5))*(1+($B$7+(G$43-$B$7)*2/5))*(1+($B$7+(G$43-$B$7)*3/5))*(1+($B$7+(G$43-$B$7)*4/5))*(1+($B$7+(G$43-$B$7)*5/5)))*$B$8)*(1+G$43))/($B$44-G$43))/(1+$B$44)^5))-$B$19+$B$18)/$B$20
B45: 0.09 | C45: =((((($F$12*(1+($B$7+(C$43-$B$7)*1/5)))*$B$8)/(1+$B$45)^1)+((($F$12*(1+($B$7+(C$43-$B$7)*1/5))*(1+($B$7+(C$43-$B$7)*2/5)))*$B$8)/(1+$B$45)^2)+((($F$12*(1+($B$7+(C$43-$B$7)*1/5))*(1+($B$7+(C$43-$B$7)*2/5))*(1+($B$7+(C$43-$B$7)*3/5)))*$B$8)/(1+$B$45)^3)+((($F$12*(1+($B$7+(C$43-$B$7)*1/5))*(1+($B$7+(C$43-$B$7)*2/5))*(1+($B$7+(C$43-$B$7)*3/5))*(1+($B$7+(C$43-$B$7)*4/5)))*$B$8)/(1+$B$45)^4)+((($F$12*(1+($B$7+(C$43-$B$7)*1/5))*(1+($B$7+(C$43-$B$7)*2/5))*(1+($B$7+(C$43-$B$7)*3/5))*(1+($B$7+(C$43-$B$7)*4/5))*(1+($B$7+(C$43-$B$7)*5/5)))*$B$8)/(1+$B$45)^5)+((((($F$12*(1+($B$7+(C$43-$B$7)*1/5))*(1+($B$7+(C$43-$B$7)*2/5))*(1+($B$7+(C$43-$B$7)*3/5))*(1+($B$7+(C$43-$B$7)*4/5))*(1+($B$7+(C$43-$B$7)*5/5)))*$B$8)*(1+C$43))/($B$45-C$43))/(1+$B$45)^5))-$B$19+$B$18)/$B$20 | D45: =((((($F$12*(1+($B$7+(D$43-$B$7)*1/5)))*$B$8)/(1+$B$45)^1)+((($F$12*(1+($B$7+(D$43-$B$7)*1/5))*(1+($B$7+(D$43-$B$7)*2/5)))*$B$8)/(1+$B$45)^2)+((($F$12*(1+($B$7+(D$43-$B$7)*1/5))*(1+($B$7+(D$43-$B$7)*2/5))*(1+($B$7+(D$43-$B$7)*3/5)))*$B$8)/(1+$B$45)^3)+((($F$12*(1+($B$7+(D$43-$B$7)*1/5))*(1+($B$7+(D$43-$B$7)*2/5))*(1+($B$7+(D$43-$B$7)*3/5))*(1+($B$7+(D$43-$B$7)*4/5)))*$B$8)/(1+$B$45)^4)+((($F$12*(1+($B$7+(D$43-$B$7)*1/5))*(1+($B$7+(D$43-$B$7)*2/5))*(1+($B$7+(D$43-$B$7)*3/5))*(1+($B$7+(D$43-$B$7)*4/5))*(1+($B$7+(D$43-$B$7)*5/5)))*$B$8)/(1+$B$45)^5)+((((($F$12*(1+($B$7+(D$43-$B$7)*1/5))*(1+($B$7+(D$43-$B$7)*2/5))*(1+($B$7+(D$43-$B$7)*3/5))*(1+($B$7+(D$43-$B$7)*4/5))*(1+($B$7+(D$43-$B$7)*5/5)))*$B$8)*(1+D$43))/($B$45-D$43))/(1+$B$45)^5))-$B$19+$B$18)/$B$20 | E45: =((((($F$12*(1+($B$7+(E$43-$B$7)*1/5)))*$B$8)/(1+$B$45)^1)+((($F$12*(1+($B$7+(E$43-$B$7)*1/5))*(1+($B$7+(E$43-$B$7)*2/5)))*$B$8)/(1+$B$45)^2)+((($F$12*(1+($B$7+(E$43-$B$7)*1/5))*(1+($B$7+(E$43-$B$7)*2/5))*(1+($B$7+(E$43-$B$7)*3/5)))*$B$8)/(1+$B$45)^3)+((($F$12*(1+($B$7+(E$43-$B$7)*1/5))*(1+($B$7+(E$43-$B$7)*2/5))*(1+($B$7+(E$43-$B$7)*3/5))*(1+($B$7+(E$43-$B$7)*4/5)))*$B$8)/(1+$B$45)^4)+((($F$12*(1+($B$7+(E$43-$B$7)*1/5))*(1+($B$7+(E$43-$B$7)*2/5))*(1+($B$7+(E$43-$B$7)*3/5))*(1+($B$7+(E$43-$B$7)*4/5))*(1+($B$7+(E$43-$B$7)*5/5)))*$B$8)/(1+$B$45)^5)+((((($F$12*(1+($B$7+(E$43-$B$7)*1/5))*(1+($B$7+(E$43-$B$7)*2/5))*(1+($B$7+(E$43-$B$7)*3/5))*(1+($B$7+(E$43-$B$7)*4/5))*(1+($B$7+(E$43-$B$7)*5/5)))*$B$8)*(1+E$43))/($B$45-E$43))/(1+$B$45)^5))-$B$19+$B$18)/$B$20 | F45: =((((($F$12*(1+($B$7+(F$43-$B$7)*1/5)))*$B$8)/(1+$B$45)^1)+((($F$12*(1+($B$7+(F$43-$B$7)*1/5))*(1+($B$7+(F$43-$B$7)*2/5)))*$B$8)/(1+$B$45)^2)+((($F$12*(1+($B$7+(F$43-$B$7)*1/5))*(1+($B$7+(F$43-$B$7)*2/5))*(1+($B$7+(F$43-$B$7)*3/5)))*$B$8)/(1+$B$45)^3)+((($F$12*(1+($B$7+(F$43-$B$7)*1/5))*(1+($B$7+(F$43-$B$7)*2/5))*(1+($B$7+(F$43-$B$7)*3/5))*(1+($B$7+(F$43-$B$7)*4/5)))*$B$8)/(1+$B$45)^4)+((($F$12*(1+($B$7+(F$43-$B$7)*1/5))*(1+($B$7+(F$43-$B$7)*2/5))*(1+($B$7+(F$43-$B$7)*3/5))*(1+($B$7+(F$43-$B$7)*4/5))*(1+($B$7+(F$43-$B$7)*5/5)))*$B$8)/(1+$B$45)^5)+((((($F$12*(1+($B$7+(F$43-$B$7)*1/5))*(1+($B$7+(F$43-$B$7)*2/5))*(1+($B$7+(F$43-$B$7)*3/5))*(1+($B$7+(F$43-$B$7)*4/5))*(1+($B$7+(F$43-$B$7)*5/5)))*$B$8)*(1+F$43))/($B$45-F$43))/(1+$B$45)^5))-$B$19+$B$18)/$B$20 | G45: =((((($F$12*(1+($B$7+(G$43-$B$7)*1/5)))*$B$8)/(1+$B$45)^1)+((($F$12*(1+($B$7+(G$43-$B$7)*1/5))*(1+($B$7+(G$43-$B$7)*2/5)))*$B$8)/(1+$B$45)^2)+((($F$12*(1+($B$7+(G$43-$B$7)*1/5))*(1+($B$7+(G$43-$B$7)*2/5))*(1+($B$7+(G$43-$B$7)*3/5)))*$B$8)/(1+$B$45)^3)+((($F$12*(1+($B$7+(G$43-$B$7)*1/5))*(1+($B$7+(G$43-$B$7)*2/5))*(1+($B$7+(G$43-$B$7)*3/5))*(1+($B$7+(G$43-$B$7)*4/5)))*$B$8)/(1+$B$45)^4)+((($F$12*(1+($B$7+(G$43-$B$7)*1/5))*(1+($B$7+(G$43-$B$7)*2/5))*(1+($B$7+(G$43-$B$7)*3/5))*(1+($B$7+(G$43-$B$7)*4/5))*(1+($B$7+(G$43-$B$7)*5/5)))*$B$8)/(1+$B$45)^5)+((((($F$12*(1+($B$7+(G$43-$B$7)*1/5))*(1+($B$7+(G$43-$B$7)*2/5))*(1+($B$7+(G$43-$B$7)*3/5))*(1+($B$7+(G$43-$B$7)*4/5))*(1+($B$7+(G$43-$B$7)*5/5)))*$B$8)*(1+G$43))/($B$45-G$43))/(1+$B$45)^5))-$B$19+$B$18)/$B$20
B46: 0.1 | C46: =((((($F$12*(1+($B$7+(C$43-$B$7)*1/5)))*$B$8)/(1+$B$46)^1)+((($F$12*(1+($B$7+(C$43-$B$7)*1/5))*(1+($B$7+(C$43-$B$7)*2/5)))*$B$8)/(1+$B$46)^2)+((($F$12*(1+($B$7+(C$43-$B$7)*1/5))*(1+($B$7+(C$43-$B$7)*2/5))*(1+($B$7+(C$43-$B$7)*3/5)))*$B$8)/(1+$B$46)^3)+((($F$12*(1+($B$7+(C$43-$B$7)*1/5))*(1+($B$7+(C$43-$B$7)*2/5))*(1+($B$7+(C$43-$B$7)*3/5))*(1+($B$7+(C$43-$B$7)*4/5)))*$B$8)/(1+$B$46)^4)+((($F$12*(1+($B$7+(C$43-$B$7)*1/5))*(1+($B$7+(C$43-$B$7)*2/5))*(1+($B$7+(C$43-$B$7)*3/5))*(1+($B$7+(C$43-$B$7)*4/5))*(1+($B$7+(C$43-$B$7)*5/5)))*$B$8)/(1+$B$46)^5)+((((($F$12*(1+($B$7+(C$43-$B$7)*1/5))*(1+($B$7+(C$43-$B$7)*2/5))*(1+($B$7+(C$43-$B$7)*3/5))*(1+($B$7+(C$43-$B$7)*4/5))*(1+($B$7+(C$43-$B$7)*5/5)))*$B$8)*(1+C$43))/($B$46-C$43))/(1+$B$46)^5))-$B$19+$B$18)/$B$20 | D46: =((((($F$12*(1+($B$7+(D$43-$B$7)*1/5)))*$B$8)/(1+$B$46)^1)+((($F$12*(1+($B$7+(D$43-$B$7)*1/5))*(1+($B$7+(D$43-$B$7)*2/5)))*$B$8)/(1+$B$46)^2)+((($F$12*(1+($B$7+(D$43-$B$7)*1/5))*(1+($B$7+(D$43-$B$7)*2/5))*(1+($B$7+(D$43-$B$7)*3/5)))*$B$8)/(1+$B$46)^3)+((($F$12*(1+($B$7+(D$43-$B$7)*1/5))*(1+($B$7+(D$43-$B$7)*2/5))*(1+($B$7+(D$43-$B$7)*3/5))*(1+($B$7+(D$43-$B$7)*4/5)))*$B$8)/(1+$B$46)^4)+((($F$12*(1+($B$7+(D$43-$B$7)*1/5))*(1+($B$7+(D$43-$B$7)*2/5))*(1+($B$7+(D$43-$B$7)*3/5))*(1+($B$7+(D$43-$B$7)*4/5))*(1+($B$7+(D$43-$B$7)*5/5)))*$B$8)/(1+$B$46)^5)+((((($F$12*(1+($B$7+(D$43-$B$7)*1/5))*(1+($B$7+(D$43-$B$7)*2/5))*(1+($B$7+(D$43-$B$7)*3/5))*(1+($B$7+(D$43-$B$7)*4/5))*(1+($B$7+(D$43-$B$7)*5/5)))*$B$8)*(1+D$43))/($B$46-D$43))/(1+$B$46)^5))-$B$19+$B$18)/$B$20 | E46: =((((($F$12*(1+($B$7+(E$43-$B$7)*1/5)))*$B$8)/(1+$B$46)^1)+((($F$12*(1+($B$7+(E$43-$B$7)*1/5))*(1+($B$7+(E$43-$B$7)*2/5)))*$B$8)/(1+$B$46)^2)+((($F$12*(1+($B$7+(E$43-$B$7)*1/5))*(1+($B$7+(E$43-$B$7)*2/5))*(1+($B$7+(E$43-$B$7)*3/5)))*$B$8)/(1+$B$46)^3)+((($F$12*(1+($B$7+(E$43-$B$7)*1/5))*(1+($B$7+(E$43-$B$7)*2/5))*(1+($B$7+(E$43-$B$7)*3/5))*(1+($B$7+(E$43-$B$7)*4/5)))*$B$8)/(1+$B$46)^4)+((($F$12*(1+($B$7+(E$43-$B$7)*1/5))*(1+($B$7+(E$43-$B$7)*2/5))*(1+($B$7+(E$43-$B$7)*3/5))*(1+($B$7+(E$43-$B$7)*4/5))*(1+($B$7+(E$43-$B$7)*5/5)))*$B$8)/(1+$B$46)^5)+((((($F$12*(1+($B$7+(E$43-$B$7)*1/5))*(1+($B$7+(E$43-$B$7)*2/5))*(1+($B$7+(E$43-$B$7)*3/5))*(1+($B$7+(E$43-$B$7)*4/5))*(1+($B$7+(E$43-$B$7)*5/5)))*$B$8)*(1+E$43))/($B$46-E$43))/(1+$B$46)^5))-$B$19+$B$18)/$B$20 | F46: =((((($F$12*(1+($B$7+(F$43-$B$7)*1/5)))*$B$8)/(1+$B$46)^1)+((($F$12*(1+($B$7+(F$43-$B$7)*1/5))*(1+($B$7+(F$43-$B$7)*2/5)))*$B$8)/(1+$B$46)^2)+((($F$12*(1+($B$7+(F$43-$B$7)*1/5))*(1+($B$7+(F$43-$B$7)*2/5))*(1+($B$7+(F$43-$B$7)*3/5)))*$B$8)/(1+$B$46)^3)+((($F$12*(1+($B$7+(F$43-$B$7)*1/5))*(1+($B$7+(F$43-$B$7)*2/5))*(1+($B$7+(F$43-$B$7)*3/5))*(1+($B$7+(F$43-$B$7)*4/5)))*$B$8)/(1+$B$46)^4)+((($F$12*(1+($B$7+(F$43-$B$7)*1/5))*(1+($B$7+(F$43-$B$7)*2/5))*(1+($B$7+(F$43-$B$7)*3/5))*(1+($B$7+(F$43-$B$7)*4/5))*(1+($B$7+(F$43-$B$7)*5/5)))*$B$8)/(1+$B$46)^5)+((((($F$12*(1+($B$7+(F$43-$B$7)*1/5))*(1+($B$7+(F$43-$B$7)*2/5))*(1+($B$7+(F$43-$B$7)*3/5))*(1+($B$7+(F$43-$B$7)*4/5))*(1+($B$7+(F$43-$B$7)*5/5)))*$B$8)*(1+F$43))/($B$46-F$43))/(1+$B$46)^5))-$B$19+$B$18)/$B$20 | G46: =((((($F$12*(1+($B$7+(G$43-$B$7)*1/5)))*$B$8)/(1+$B$46)^1)+((($F$12*(1+($B$7+(G$43-$B$7)*1/5))*(1+($B$7+(G$43-$B$7)*2/5)))*$B$8)/(1+$B$46)^2)+((($F$12*(1+($B$7+(G$43-$B$7)*1/5))*(1+($B$7+(G$43-$B$7)*2/5))*(1+($B$7+(G$43-$B$7)*3/5)))*$B$8)/(1+$B$46)^3)+((($F$12*(1+($B$7+(G$43-$B$7)*1/5))*(1+($B$7+(G$43-$B$7)*2/5))*(1+($B$7+(G$43-$B$7)*3/5))*(1+($B$7+(G$43-$B$7)*4/5)))*$B$8)/(1+$B$46)^4)+((($F$12*(1+($B$7+(G$43-$B$7)*1/5))*(1+($B$7+(G$43-$B$7)*2/5))*(1+($B$7+(G$43-$B$7)*3/5))*(1+($B$7+(G$43-$B$7)*4/5))*(1+($B$7+(G$43-$B$7)*5/5)))*$B$8)/(1+$B$46)^5)+((((($F$12*(1+($B$7+(G$43-$B$7)*1/5))*(1+($B$7+(G$43-$B$7)*2/5))*(1+($B$7+(G$43-$B$7)*3/5))*(1+($B$7+(G$43-$B$7)*4/5))*(1+($B$7+(G$43-$B$7)*5/5)))*$B$8)*(1+G$43))/($B$46-G$43))/(1+$B$46)^5))-$B$19+$B$18)/$B$20
...

Sheet WDAY
A1: WDAY — Workday, Inc.
A2: Unlevered DCF | $ in millions except per-share and share count
A4: Assumptions (edit the highlighted cells)
A5: WACC (discount rate) | B5: 0.1
A6: Terminal growth rate | B6: 0.03
A7: Starting revenue growth rate | B7: 0.13094956 | C7: default: most recent YoY revenue growth
A8: Unlevered FCF margin (% of revenue) | B8: 0.2751278 | C8: default: avg of last 2 fiscal years' FCF / revenue
A10: Historical Trend ($ in millions)
A11: Fiscal year | B11: 2022 | C11: 2023 | D11: 2024 | E11: 2025 | F11: 2026
A12: Revenue | B12: 5139 | C12: 6216 | D12: 7259 | E12: 8446 | F12: 9552
A13: Revenue growth % | C13: =C12/B12-1 | D13: =D12/C12-1 | E13: =E12/D12-1 | F13: =F12/E12-1
A14: Free cash flow | C14: 1293 | D14: 1917 | E14: 2192 | F14: 2777
A15: FCF margin % | C15: =C14/C12 | D15: =D14/D12 | E15: =E14/E12 | F15: =F14/F12
A17: Balance Sheet Actuals — FY2026 ($ in millions)
A18: Cash & equivalents | B18: 1501
A19: Total debt | B19: 2987
A20: Diluted shares outstanding (millions) | B20: 268.117
A22: 5-Year Projection ($ in millions)
A23: Fiscal year | B23: FY2027E | C23: FY2028E | D23: FY2029E | E23: FY2030E | F23: FY2031E
A24: Revenue growth rate | B24: =$B$7+($B$6-$B$7)*1/5 | C24: =$B$7+($B$6-$B$7)*2/5 | D24: =$B$7+($B$6-$B$7)*3/5 | E24: =$B$7+($B$6-$B$7)*4/5 | F24: =$B$7+($B$6-$B$7)*5/5
A25: Projected revenue | B25: =F12*(1+B24) | C25: =B25*(1+C24) | D25: =C25*(1+D24) | E25: =D25*(1+E24) | F25: =E25*(1+F24)
A26: FCF margin (assumption, held flat) | B26: =$B$8 | C26: =$B$8 | D26: =$B$8 | E26: =$B$8 | F26: =$B$8
A27: Projected unlevered FCF | B27: =B25*B26 | C27: =C25*C26 | D27: =D25*D26 | E27: =E25*E26 | F27: =F25*F26
A28: Discount factor | B28: =1/(1+$B$5)^1 | C28: =1/(1+$B$5)^2 | D28: =1/(1+$B$5)^3 | E28: =1/(1+$B$5)^4 | F28: =1/(1+$B$5)^5
A29: PV of FCF | B29: =B27*B28 | C29: =C27*C28 | D29: =D27*D28 | E29: =E27*E28 | F29: =F27*F28
A31: Terminal Value & Valuation
A32: Terminal value (end of FY2031) | B32: =F27*(1+$B$6)/($B$5-$B$6)
A33: PV of terminal value | B33: =B32*F28
A34: Sum of PV of projected FCFs | B34: =SUM(B29:F29)
A35: Enterprise value | B35: =B33+B34
A36: Less: total debt | B36: =-B19
A37: Plus: cash & equivalents | B37: =B18
A38: Equity value | B38: =B35+B36+B37
A39: Diluted shares outstanding (millions) | B39: =B20
A40: Implied value per share | B40: =B38/B39
A42: Sensitivity: Implied Value/Share (WACC x Terminal Growth)
B43: WACC \ Term. g | C43: 0.02 | D43: 0.025 | E43: 0.03 | F43: 0.035 | G43: 0.04
B44: 0.08 | C44: =((((($F$12*(1+($B$7+(C$43-$B$7)*1/5)))*$B$8)/(1+$B$44)^1)+((($F$12*(1+($B$7+(C$43-$B$7)*1/5))*(1+($B$7+(C$43-$B$7)*2/5)))*$B$8)/(1+$B$44)^2)+((($F$12*(1+($B$7+(C$43-$B$7)*1/5))*(1+($B$7+(C$43-$B$7)*2/5))*(1+($B$7+(C$43-$B$7)*3/5)))*$B$8)/(1+$B$44)^3)+((($F$12*(1+($B$7+(C$43-$B$7)*1/5))*(1+($B$7+(C$43-$B$7)*2/5))*(1+($B$7+(C$43-$B$7)*3/5))*(1+($B$7+(C$43-$B$7)*4/5)))*$B$8)/(1+$B$44)^4)+((($F$12*(1+($B$7+(C$43-$B$7)*1/5))*(1+($B$7+(C$43-$B$7)*2/5))*(1+($B$7+(C$43-$B$7)*3/5))*(1+($B$7+(C$43-$B$7)*4/5))*(1+($B$7+(C$43-$B$7)*5/5)))*$B$8)/(1+$B$44)^5)+((((($F$12*(1+($B$7+(C$43-$B$7)*1/5))*(1+($B$7+(C$43-$B$7)*2/5))*(1+($B$7+(C$43-$B$7)*3/5))*(1+($B$7+(C$43-$B$7)*4/5))*(1+($B$7+(C$43-$B$7)*5/5)))*$B$8)*(1+C$43))/($B$44-C$43))/(1+$B$44)^5))-$B$19+$B$18)/$B$20 | D44: =((((($F$12*(1+($B$7+(D$43-$B$7)*1/5)))*$B$8)/(1+$B$44)^1)+((($F$12*(1+($B$7+(D$43-$B$7)*1/5))*(1+($B$7+(D$43-$B$7)*2/5)))*$B$8)/(1+$B$44)^2)+((($F$12*(1+($B$7+(D$43-$B$7)*1/5))*(1+($B$7+(D$43-$B$7)*2/5))*(1+($B$7+(D$43-$B$7)*3/5)))*$B$8)/(1+$B$44)^3)+((($F$12*(1+($B$7+(D$43-$B$7)*1/5))*(1+($B$7+(D$43-$B$7)*2/5))*(1+($B$7+(D$43-$B$7)*3/5))*(1+($B$7+(D$43-$B$7)*4/5)))*$B$8)/(1+$B$44)^4)+((($F$12*(1+($B$7+(D$43-$B$7)*1/5))*(1+($B$7+(D$43-$B$7)*2/5))*(1+($B$7+(D$43-$B$7)*3/5))*(1+($B$7+(D$43-$B$7)*4/5))*(1+($B$7+(D$43-$B$7)*5/5)))*$B$8)/(1+$B$44)^5)+((((($F$12*(1+($B$7+(D$43-$B$7)*1/5))*(1+($B$7+(D$43-$B$7)*2/5))*(1+($B$7+(D$43-$B$7)*3/5))*(1+($B$7+(D$43-$B$7)*4/5))*(1+($B$7+(D$43-$B$7)*5/5)))*$B$8)*(1+D$43))/($B$44-D$43))/(1+$B$44)^5))-$B$19+$B$18)/$B$20 | E44: =((((($F$12*(1+($B$7+(E$43-$B$7)*1/5)))*$B$8)/(1+$B$44)^1)+((($F$12*(1+($B$7+(E$43-$B$7)*1/5))*(1+($B$7+(E$43-$B$7)*2/5)))*$B$8)/(1+$B$44)^2)+((($F$12*(1+($B$7+(E$43-$B$7)*1/5))*(1+($B$7+(E$43-$B$7)*2/5))*(1+($B$7+(E$43-$B$7)*3/5)))*$B$8)/(1+$B$44)^3)+((($F$12*(1+($B$7+(E$43-$B$7)*1/5))*(1+($B$7+(E$43-$B$7)*2/5))*(1+($B$7+(E$43-$B$7)*3/5))*(1+($B$7+(E$43-$B$7)*4/5)))*$B$8)/(1+$B$44)^4)+((($F$12*(1+($B$7+(E$43-$B$7)*1/5))*(1+($B$7+(E$43-$B$7)*2/5))*(1+($B$7+(E$43-$B$7)*3/5))*(1+($B$7+(E$43-$B$7)*4/5))*(1+($B$7+(E$43-$B$7)*5/5)))*$B$8)/(1+$B$44)^5)+((((($F$12*(1+($B$7+(E$43-$B$7)*1/5))*(1+($B$7+(E$43-$B$7)*2/5))*(1+($B$7+(E$43-$B$7)*3/5))*(1+($B$7+(E$43-$B$7)*4/5))*(1+($B$7+(E$43-$B$7)*5/5)))*$B$8)*(1+E$43))/($B$44-E$43))/(1+$B$44)^5))-$B$19+$B$18)/$B$20 | F44: =((((($F$12*(1+($B$7+(F$43-$B$7)*1/5)))*$B$8)/(1+$B$44)^1)+((($F$12*(1+($B$7+(F$43-$B$7)*1/5))*(1+($B$7+(F$43-$B$7)*2/5)))*$B$8)/(1+$B$44)^2)+((($F$12*(1+($B$7+(F$43-$B$7)*1/5))*(1+($B$7+(F$43-$B$7)*2/5))*(1+($B$7+(F$43-$B$7)*3/5)))*$B$8)/(1+$B$44)^3)+((($F$12*(1+($B$7+(F$43-$B$7)*1/5))*(1+($B$7+(F$43-$B$7)*2/5))*(1+($B$7+(F$43-$B$7)*3/5))*(1+($B$7+(F$43-$B$7)*4/5)))*$B$8)/(1+$B$44)^4)+((($F$12*(1+($B$7+(F$43-$B$7)*1/5))*(1+($B$7+(F$43-$B$7)*2/5))*(1+($B$7+(F$43-$B$7)*3/5))*(1+($B$7+(F$43-$B$7)*4/5))*(1+($B$7+(F$43-$B$7)*5/5)))*$B$8)/(1+$B$44)^5)+((((($F$12*(1+($B$7+(F$43-$B$7)*1/5))*(1+($B$7+(F$43-$B$7)*2/5))*(1+($B$7+(F$43-$B$7)*3/5))*(1+($B$7+(F$43-$B$7)*4/5))*(1+($B$7+(F$43-$B$7)*5/5)))*$B$8)*(1+F$43))/($B$44-F$43))/(1+$B$44)^5))-$B$19+$B$18)/$B$20 | G44: =((((($F$12*(1+($B$7+(G$43-$B$7)*1/5)))*$B$8)/(1+$B$44)^1)+((($F$12*(1+($B$7+(G$43-$B$7)*1/5))*(1+($B$7+(G$43-$B$7)*2/5)))*$B$8)/(1+$B$44)^2)+((($F$12*(1+($B$7+(G$43-$B$7)*1/5))*(1+($B$7+(G$43-$B$7)*2/5))*(1+($B$7+(G$43-$B$7)*3/5)))*$B$8)/(1+$B$44)^3)+((($F$12*(1+($B$7+(G$43-$B$7)*1/5))*(1+($B$7+(G$43-$B$7)*2/5))*(1+($B$7+(G$43-$B$7)*3/5))*(1+($B$7+(G$43-$B$7)*4/5)))*$B$8)/(1+$B$44)^4)+((($F$12*(1+($B$7+(G$43-$B$7)*1/5))*(1+($B$7+(G$43-$B$7)*2/5))*(1+($B$7+(G$43-$B$7)*3/5))*(1+($B$7+(G$43-$B$7)*4/5))*(1+($B$7+(G$43-$B$7)*5/5)))*$B$8)/(1+$B$44)^5)+((((($F$12*(1+($B$7+(G$43-$B$7)*1/5))*(1+($B$7+(G$43-$B$7)*2/5))*(1+($B$7+(G$43-$B$7)*3/5))*(1+($B$7+(G$43-$B$7)*4/5))*(1+($B$7+(G$43-$B$7)*5/5)))*$B$8)*(1+G$43))/($B$44-G$43))/(1+$B$44)^5))-$B$19+$B$18)/$B$20
B45: 0.09 | C45: =((((($F$12*(1+($B$7+(C$43-$B$7)*1/5)))*$B$8)/(1+$B$45)^1)+((($F$12*(1+($B$7+(C$43-$B$7)*1/5))*(1+($B$7+(C$43-$B$7)*2/5)))*$B$8)/(1+$B$45)^2)+((($F$12*(1+($B$7+(C$43-$B$7)*1/5))*(1+($B$7+(C$43-$B$7)*2/5))*(1+($B$7+(C$43-$B$7)*3/5)))*$B$8)/(1+$B$45)^3)+((($F$12*(1+($B$7+(C$43-$B$7)*1/5))*(1+($B$7+(C$43-$B$7)*2/5))*(1+($B$7+(C$43-$B$7)*3/5))*(1+($B$7+(C$43-$B$7)*4/5)))*$B$8)/(1+$B$45)^4)+((($F$12*(1+($B$7+(C$43-$B$7)*1/5))*(1+($B$7+(C$43-$B$7)*2/5))*(1+($B$7+(C$43-$B$7)*3/5))*(1+($B$7+(C$43-$B$7)*4/5))*(1+($B$7+(C$43-$B$7)*5/5)))*$B$8)/(1+$B$45)^5)+((((($F$12*(1+($B$7+(C$43-$B$7)*1/5))*(1+($B$7+(C$43-$B$7)*2/5))*(1+($B$7+(C$43-$B$7)*3/5))*(1+($B$7+(C$43-$B$7)*4/5))*(1+($B$7+(C$43-$B$7)*5/5)))*$B$8)*(1+C$43))/($B$45-C$43))/(1+$B$45)^5))-$B$19+$B$18)/$B$20 | D45: =((((($F$12*(1+($B$7+(D$43-$B$7)*1/5)))*$B$8)/(1+$B$45)^1)+((($F$12*(1+($B$7+(D$43-$B$7)*1/5))*(1+($B$7+(D$43-$B$7)*2/5)))*$B$8)/(1+$B$45)^2)+((($F$12*(1+($B$7+(D$43-$B$7)*1/5))*(1+($B$7+(D$43-$B$7)*2/5))*(1+($B$7+(D$43-$B$7)*3/5)))*$B$8)/(1+$B$45)^3)+((($F$12*(1+($B$7+(D$43-$B$7)*1/5))*(1+($B$7+(D$43-$B$7)*2/5))*(1+($B$7+(D$43-$B$7)*3/5))*(1+($B$7+(D$43-$B$7)*4/5)))*$B$8)/(1+$B$45)^4)+((($F$12*(1+($B$7+(D$43-$B$7)*1/5))*(1+($B$7+(D$43-$B$7)*2/5))*(1+($B$7+(D$43-$B$7)*3/5))*(1+($B$7+(D$43-$B$7)*4/5))*(1+($B$7+(D$43-$B$7)*5/5)))*$B$8)/(1+$B$45)^5)+((((($F$12*(1+($B$7+(D$43-$B$7)*1/5))*(1+($B$7+(D$43-$B$7)*2/5))*(1+($B$7+(D$43-$B$7)*3/5))*(1+($B$7+(D$43-$B$7)*4/5))*(1+($B$7+(D$43-$B$7)*5/5)))*$B$8)*(1+D$43))/($B$45-D$43))/(1+$B$45)^5))-$B$19+$B$18)/$B$20 | E45: =((((($F$12*(1+($B$7+(E$43-$B$7)*1/5)))*$B$8)/(1+$B$45)^1)+((($F$12*(1+($B$7+(E$43-$B$7)*1/5))*(1+($B$7+(E$43-$B$7)*2/5)))*$B$8)/(1+$B$45)^2)+((($F$12*(1+($B$7+(E$43-$B$7)*1/5))*(1+($B$7+(E$43-$B$7)*2/5))*(1+($B$7+(E$43-$B$7)*3/5)))*$B$8)/(1+$B$45)^3)+((($F$12*(1+($B$7+(E$43-$B$7)*1/5))*(1+($B$7+(E$43-$B$7)*2/5))*(1+($B$7+(E$43-$B$7)*3/5))*(1+($B$7+(E$43-$B$7)*4/5)))*$B$8)/(1+$B$45)^4)+((($F$12*(1+($B$7+(E$43-$B$7)*1/5))*(1+($B$7+(E$43-$B$7)*2/5))*(1+($B$7+(E$43-$B$7)*3/5))*(1+($B$7+(E$43-$B$7)*4/5))*(1+($B$7+(E$43-$B$7)*5/5)))*$B$8)/(1+$B$45)^5)+((((($F$12*(1+($B$7+(E$43-$B$7)*1/5))*(1+($B$7+(E$43-$B$7)*2/5))*(1+($B$7+(E$43-$B$7)*3/5))*(1+($B$7+(E$43-$B$7)*4/5))*(1+($B$7+(E$43-$B$7)*5/5)))*$B$8)*(1+E$43))/($B$45-E$43))/(1+$B$45)^5))-$B$19+$B$18)/$B$20 | F45: =((((($F$12*(1+($B$7+(F$43-$B$7)*1/5)))*$B$8)/(1+$B$45)^1)+((($F$12*(1+($B$7+(F$43-$B$7)*1/5))*(1+($B$7+(F$43-$B$7)*2/5)))*$B$8)/(1+$B$45)^2)+((($F$12*(1+($B$7+(F$43-$B$7)*1/5))*(1+($B$7+(F$43-$B$7)*2/5))*(1+($B$7+(F$43-$B$7)*3/5)))*$B$8)/(1+$B$45)^3)+((($F$12*(1+($B$7+(F$43-$B$7)*1/5))*(1+($B$7+(F$43-$B$7)*2/5))*(1+($B$7+(F$43-$B$7)*3/5))*(1+($B$7+(F$43-$B$7)*4/5)))*$B$8)/(1+$B$45)^4)+((($F$12*(1+($B$7+(F$43-$B$7)*1/5))*(1+($B$7+(F$43-$B$7)*2/5))*(1+($B$7+(F$43-$B$7)*3/5))*(1+($B$7+(F$43-$B$7)*4/5))*(1+($B$7+(F$43-$B$7)*5/5)))*$B$8)/(1+$B$45)^5)+((((($F$12*(1+($B$7+(F$43-$B$7)*1/5))*(1+($B$7+(F$43-$B$7)*2/5))*(1+($B$7+(F$43-$B$7)*3/5))*(1+($B$7+(F$43-$B$7)*4/5))*(1+($B$7+(F$43-$B$7)*5/5)))*$B$8)*(1+F$43))/($B$45-F$43))/(1+$B$45)^5))-$B$19+$B$18)/$B$20 | G45: =((((($F$12*(1+($B$7+(G$43-$B$7)*1/5)))*$B$8)/(1+$B$45)^1)+((($F$12*(1+($B$7+(G$43-$B$7)*1/5))*(1+($B$7+(G$43-$B$7)*2/5)))*$B$8)/(1+$B$45)^2)+((($F$12*(1+($B$7+(G$43-$B$7)*1/5))*(1+($B$7+(G$43-$B$7)*2/5))*(1+($B$7+(G$43-$B$7)*3/5)))*$B$8)/(1+$B$45)^3)+((($F$12*(1+($B$7+(G$43-$B$7)*1/5))*(1+($B$7+(G$43-$B$7)*2/5))*(1+($B$7+(G$43-$B$7)*3/5))*(1+($B$7+(G$43-$B$7)*4/5)))*$B$8)/(1+$B$45)^4)+((($F$12*(1+($B$7+(G$43-$B$7)*1/5))*(1+($B$7+(G$43-$B$7)*2/5))*(1+($B$7+(G$43-$B$7)*3/5))*(1+($B$7+(G$43-$B$7)*4/5))*(1+($B$7+(G$43-$B$7)*5/5)))*$B$8)/(1+$B$45)^5)+((((($F$12*(1+($B$7+(G$43-$B$7)*1/5))*(1+($B$7+(G$43-$B$7)*2/5))*(1+($B$7+(G$43-$B$7)*3/5))*(1+($B$7+(G$43-$B$7)*4/5))*(1+($B$7+(G$43-$B$7)*5/5)))*$B$8)*(1+G$43))/($B$45-G$43))/(1+$B$45)^5))-$B$19+$B$18)/$B$20
B46: 0.1 | C46: =((((($F$12*(1+($B$7+(C$43-$B$7)*1/5)))*$B$8)/(1+$B$46)^1)+((($F$12*(1+($B$7+(C$43-$B$7)*1/5))*(1+($B$7+(C$43-$B$7)*2/5)))*$B$8)/(1+$B$46)^2)+((($F$12*(1+($B$7+(C$43-$B$7)*1/5))*(1+($B$7+(C$43-$B$7)*2/5))*(1+($B$7+(C$43-$B$7)*3/5)))*$B$8)/(1+$B$46)^3)+((($F$12*(1+($B$7+(C$43-$B$7)*1/5))*(1+($B$7+(C$43-$B$7)*2/5))*(1+($B$7+(C$43-$B$7)*3/5))*(1+($B$7+(C$43-$B$7)*4/5)))*$B$8)/(1+$B$46)^4)+((($F$12*(1+($B$7+(C$43-$B$7)*1/5))*(1+($B$7+(C$43-$B$7)*2/5))*(1+($B$7+(C$43-$B$7)*3/5))*(1+($B$7+(C$43-$B$7)*4/5))*(1+($B$7+(C$43-$B$7)*5/5)))*$B$8)/(1+$B$46)^5)+((((($F$12*(1+($B$7+(C$43-$B$7)*1/5))*(1+($B$7+(C$43-$B$7)*2/5))*(1+($B$7+(C$43-$B$7)*3/5))*(1+($B$7+(C$43-$B$7)*4/5))*(1+($B$7+(C$43-$B$7)*5/5)))*$B$8)*(1+C$43))/($B$46-C$43))/(1+$B$46)^5))-$B$19+$B$18)/$B$20 | D46: =((((($F$12*(1+($B$7+(D$43-$B$7)*1/5)))*$B$8)/(1+$B$46)^1)+((($F$12*(1+($B$7+(D$43-$B$7)*1/5))*(1+($B$7+(D$43-$B$7)*2/5)))*$B$8)/(1+$B$46)^2)+((($F$12*(1+($B$7+(D$43-$B$7)*1/5))*(1+($B$7+(D$43-$B$7)*2/5))*(1+($B$7+(D$43-$B$7)*3/5)))*$B$8)/(1+$B$46)^3)+((($F$12*(1+($B$7+(D$43-$B$7)*1/5))*(1+($B$7+(D$43-$B$7)*2/5))*(1+($B$7+(D$43-$B$7)*3/5))*(1+($B$7+(D$43-$B$7)*4/5)))*$B$8)/(1+$B$46)^4)+((($F$12*(1+($B$7+(D$43-$B$7)*1/5))*(1+($B$7+(D$43-$B$7)*2/5))*(1+($B$7+(D$43-$B$7)*3/5))*(1+($B$7+(D$43-$B$7)*4/5))*(1+($B$7+(D$43-$B$7)*5/5)))*$B$8)/(1+$B$46)^5)+((((($F$12*(1+($B$7+(D$43-$B$7)*1/5))*(1+($B$7+(D$43-$B$7)*2/5))*(1+($B$7+(D$43-$B$7)*3/5))*(1+($B$7+(D$43-$B$7)*4/5))*(1+($B$7+(D$43-$B$7)*5/5)))*$B$8)*(1+D$43))/($B$46-D$43))/(1+$B$46)^5))-$B$19+$B$18)/$B$20 | E46: =((((($F$12*(1+($B$7+(E$43-$B$7)*1/5)))*$B$8)/(1+$B$46)^1)+((($F$12*(1+($B$7+(E$43-$B$7)*1/5))*(1+($B$7+(E$43-$B$7)*2/5)))*$B$8)/(1+$B$46)^2)+((($F$12*(1+($B$7+(E$43-$B$7)*1/5))*(1+($B$7+(E$43-$B$7)*2/5))*(1+($B$7+(E$43-$B$7)*3/5)))*$B$8)/(1+$B$46)^3)+((($F$12*(1+($B$7+(E$43-$B$7)*1/5))*(1+($B$7+(E$43-$B$7)*2/5))*(1+($B$7+(E$43-$B$7)*3/5))*(1+($B$7+(E$43-$B$7)*4/5)))*$B$8)/(1+$B$46)^4)+((($F$12*(1+($B$7+(E$43-$B$7)*1/5))*(1+($B$7+(E$43-$B$7)*2/5))*(1+($B$7+(E$43-$B$7)*3/5))*(1+($B$7+(E$43-$B$7)*4/5))*(1+($B$7+(E$43-$B$7)*5/5)))*$B$8)/(1+$B$46)^5)+((((($F$12*(1+($B$7+(E$43-$B$7)*1/5))*(1+($B$7+(E$43-$B$7)*2/5))*(1+($B$7+(E$43-$B$7)*3/5))*(1+($B$7+(E$43-$B$7)*4/5))*(1+($B$7+(E$43-$B$7)*5/5)))*$B$8)*(1+E$43))/($B$46-E$43))/(1+$B$46)^5))-$B$19+$B$18)/$B$20 | F46: =((((($F$12*(1+($B$7+(F$43-$B$7)*1/5)))*$B$8)/(1+$B$46)^1)+((($F$12*(1+($B$7+(F$43-$B$7)*1/5))*(1+($B$7+(F$43-$B$7)*2/5)))*$B$8)/(1+$B$46)^2)+((($F$12*(1+($B$7+(F$43-$B$7)*1/5))*(1+($B$7+(F$43-$B$7)*2/5))*(1+($B$7+(F$43-$B$7)*3/5)))*$B$8)/(1+$B$46)^3)+((($F$12*(1+($B$7+(F$43-$B$7)*1/5))*(1+($B$7+(F$43-$B$7)*2/5))*(1+($B$7+(F$43-$B$7)*3/5))*(1+($B$7+(F$43-$B$7)*4/5)))*$B$8)/(1+$B$46)^4)+((($F$12*(1+($B$7+(F$43-$B$7)*1/5))*(1+($B$7+(F$43-$B$7)*2/5))*(1+($B$7+(F$43-$B$7)*3/5))*(1+($B$7+(F$43-$B$7)*4/5))*(1+($B$7+(F$43-$B$7)*5/5)))*$B$8)/(1+$B$46)^5)+((((($F$12*(1+($B$7+(F$43-$B$7)*1/5))*(1+($B$7+(F$43-$B$7)*2/5))*(1+($B$7+(F$43-$B$7)*3/5))*(1+($B$7+(F$43-$B$7)*4/5))*(1+($B$7+(F$43-$B$7)*5/5)))*$B$8)*(1+F$43))/($B$46-F$43))/(1+$B$46)^5))-$B$19+$B$18)/$B$20 | G46: =((((($F$12*(1+($B$7+(G$43-$B$7)*1/5)))*$B$8)/(1+$B$46)^1)+((($F$12*(1+($B$7+(G$43-$B$7)*1/5))*(1+($B$7+(G$43-$B$7)*2/5)))*$B$8)/(1+$B$46)^2)+((($F$12*(1+($B$7+(G$43-$B$7)*1/5))*(1+($B$7+(G$43-$B$7)*2/5))*(1+($B$7+(G$43-$B$7)*3/5)))*$B$8)/(1+$B$46)^3)+((($F$12*(1+($B$7+(G$43-$B$7)*1/5))*(1+($B$7+(G$43-$B$7)*2/5))*(1+($B$7+(G$43-$B$7)*3/5))*(1+($B$7+(G$43-$B$7)*4/5)))*$B$8)/(1+$B$46)^4)+((($F$12*(1+($B$7+(G$43-$B$7)*1/5))*(1+($B$7+(G$43-$B$7)*2/5))*(1+($B$7+(G$43-$B$7)*3/5))*(1+($B$7+(G$43-$B$7)*4/5))*(1+($B$7+(G$43-$B$7)*5/5)))*$B$8)/(1+$B$46)^5)+((((($F$12*(1+($B$7+(G$43-$B$7)*1/5))*(1+($B$7+(G$43-$B$7)*2/5))*(1+($B$7+(G$43-$B$7)*3/5))*(1+($B$7+(G$43-$B$7)*4/5))*(1+($B$7+(G$43-$B$7)*5/5)))*$B$8)*(1+G$43))/($B$46-G$43))/(1+$B$46)^5))-$B$19+$B$18)/$B$20
...

Sheet HUBS
A1: HUBS — HubSpot Inc
A2: Unlevered DCF | $ in millions except per-share and share count
A4: Assumptions (edit the highlighted cells)
A5: WACC (discount rate) | B5: 0.1
A6: Terminal growth rate | B6: 0.03
A7: Starting revenue growth rate | B7: 0.19170876 | C7: default: most recent YoY revenue growth
